Workbook

Sheet DuLieu
A1: Dấu thời gian | B1: Họ và tên Nhân Viên | C1: Ngày báo Cáo | D1: Bán Fiber | E1: Bán MyTV | F1: Bán Camera_Mesh | G1: Ngưng Fiber | H1: Ngưng Mytv | I1: Chuyển ONT 2B | J1: Chuyển XGSPON | K1: GHTT tháng T | L1: GHTT tháng T+1 | M1: Lắp đặt/Dịch chuyển | N1: Thu hồi ONT 2B | O1: Thu hồi Mesh | P1: Xử Lý Suy Hao | Q1: Sửa chữa | R1: B2A | S1: Tiền Suy Hao | T1: Ngày | U1: Tháng | V1: Nam | W1: Ghi chú
B2: Tổng | D2: =SUM(D3:D11894) | E2: =SUM(E3:E11894) | F2: =SUM(F3:F11894) | G2: =SUM(G3:G11894) | H2: =SUM(H3:H11894) | I2: =SUM(I3:I11894) | J2: =SUM(J3:J11894) | K2: =SUM(K3:K11894) | ... S2: =SUM(S3:S11894)
A3: 45975.405 | B3: Trần Trung Giang | C3: 45962 | D3: 0 | E3: 0 | F3: 0 | G3: 0 | H3: 0 | I3: 0 | J3: 0 | K3: 0 | L3: 0 | M3: 0 | N3: 0 | O3: 0 | P3: 0 | Q3: 0 | R3: 0 | T3: =DAY(C3) | U3: =MONTH(C3) | V3: 2025 | W3: Không xoa dòng này
A4: 45975.455 | B4: Lương Duy Hoàng | C4: 45974 | D4: 0 | E4: 0 | F4: 0 | G4: 0 | H4: 0 | I4: 0 | J4: 0 | K4: 3 | L4: 0 | M4: 1 | N4: 2 | O4: 0 | P4: 1 | Q4: 3 | R4: 0 | T4: =DAY(C4) | U4: =MONTH(C4) | V4: 2025
A5: 45975.456 | B5: Hồ Thái Minh Trí | C5: 45974 | D5: 0 | E5: 0 | F5: 0 | G5: 0 | H5: 0 | I5: 0 | J5: 0 | K5: 9 | L5: 2 | M5: 0 | N5: 0 | O5: 0 | P5: 0 | Q5: 2 | R5: 0 | T5: =DAY(C5) | U5: =MONTH(C5) | V5: 2025
A6: 45975.457 | B6: Lê Văn Hồng | C6: 45974 | D6: 0 | E6: 0 | F6: 0 | G6: 0 | H6: 0 | I6: 3 | J6: 1 | K6: 7 | L6: 2 | M6: 1 | N6: 0 | O6: 0 | P6: 1 | Q6: 4 | R6: 0 | T6: =DAY(C6) | U6: =MONTH(C6) | V6: 2025
A7: 45975.457 | B7: Lê Quốc Duy | C7: 45974 | D7: 0 | E7: 0 | F7: 0 | G7: 0 | H7: 0 | I7: 0 | J7: 0 | K7: 13 | L7: 0 | M7: 1 | N7: 0 | O7: 0 | P7: 2 | Q7: 4 | R7: 0 | T7: =DAY(C7) | U7: =MONTH(C7) | V7: 2025
A8: 45975.459 | B8: Vòng Nhật Sang | C8: 45974 | D8: 1 | E8: 1 | F8: 0 | G8: 0 | H8: 0 | I8: 0 | J8: 0 | K8: 29 | L8: 0 | M8: 0 | N8: 0 | O8: 0 | P8: 0 | Q8: 5 | R8: 0 | T8: =DAY(C8) | U8: =MONTH(C8) | V8: 2025
A9: 45975.46 | B9: Nguyễn Tuấn Anh | C9: 45975 | D9: 0 | E9: 0 | F9: 0 | G9: 0 | H9: 0 | I9: 0 | J9: 0 | K9: 27 | L9: 0 | M9: 0 | N9: 0 | O9: 0 | P9: 1 | Q9: 1 | R9: 0 | T9: =DAY(C9) | U9: =MONTH(C9) | V9: 2025
A10: 45975.464 | B10: Dương Minh Tiến | C10: 45974 | D10: 0 | E10: 0 | F10: 0 | G10: 0 | H10: 0 | I10: 1 | J10: 0 | K10: 18 | L10: 0 | M10: 1 | N10: 0 | O10: 0 | P10: 0 | Q10: 2 | R10: 0 | T10: =DAY(C10) | U10: =MONTH(C10) | V10: 2025
A11: 45975.464 | B11: Phan Thành Thái | C11: 45974 | D11: 1 | E11: 1 | F11: 1 | G11: 1 | I11: 2 | J11: 0 | K11: 4 | L11: 0 | M11: 2 | N11: 0 | O11: 0 | P11: 1 | Q11: 4 | R11: 0 | T11: =DAY(C11) | U11: =MONTH(C11) | V11: 2025
A12: 45975.465 | B12: Đặng Hoài Anh | C12: 45974 | D12: 0 | E12: 0 | F12: 0 | G12: 1 | H12: 1 | I12: 0 | J12: 0 | K12: 5 | L12: 0 | M12: 0 | N12: 0 | O12: 0 | P12: 0 | Q12: 0 | R12: 0 | T12: =DAY(C12) | U12: =MONTH(C12) | V12: 2025
A13: 45975.468 | B13: Nguyễn Quang Anh Tuấn | C13: 45974 | D13: 0 | E13: 0 | F13: 0 | G13: 0 | H13: 0 | I13: 1 | J13: 0 | K13: 3 | L13: 0 | M13: 0 | N13: 0 | O13: 0 | P13: 0 | Q13: 0 | R13: 0 | T13: =DAY(C13) | U13: =MONTH(C13) | V13: 2025
A14: 45975.469 | B14: Nguyễn Thành Lâm | C14: 45974 | D14: 0 | E14: 0 | F14: 0 | G14: 3 | H14: 2 | I14: 0 | J14: 0 | K14: 9 | L14: 1 | M14: 0 | N14: 1 | O14: 0 | P14: 0 | Q14: 3 | R14: 0 | T14: =DAY(C14) | U14: =MONTH(C14) | V14: 2025
A15: 45975.47 | B15: Đào Công Trung | C15: 45974 | D15: 1 | E15: 1 | F15: 0 | G15: 0 | I15: 0 | J15: 0 | K15: 5 | L15: 0 | M15: 1 | N15: 0 | O15: 0 | P15: 0 | Q15: 1 | R15: 0 | T15: =DAY(C15) | U15: =MONTH(C15) | V15: 2025
A16: 45975.471 | B16: Phan Ngọc Sang | C16: 45974 | D16: 0 | E16: 1 | F16: 0 | G16: 0 | I16: 0 | J16: 0 | K16: 9 | L16: 0 | M16: 2 | N16: 0 | O16: 0 | P16: 1 | Q16: 1 | R16: 0 | T16: =DAY(C16) | U16: =MONTH(C16) | V16: 2025
A17: 45975.481 | B17: Hồ Xuân Việt | C17: 45975 | D17: 0 | E17: 0 | F17: 0 | G17: 0 | H17: 0 | I17: 0 | J17: 0 | K17: 0 | L17: 0 | M17: 1 | N17: 0 | O17: 0 | P17: 1 | Q17: 2 | R17: 0 | T17: =DAY(C17) | U17: =MONTH(C17) | V17: 2025
A18: 45975.482 | B18: Lương Duy Hải | C18: 45974 | D18: 0 | E18: 0 | F18: 0 | G18: 1 | H18: 1 | I18: 1 | J18: 1 | K18: 6 | L18: 0 | M18: 0 | N18: 1 | O18: 0 | P18: 0 | Q18: 2 | R18: 2 | T18: =DAY(C18) | U18: =MONTH(C18) | V18: 2025
A19: 45975.484 | B19: Nguyễn Văn Hiệp | C19: 45974 | D19: 0 | E19: 0 | F19: 0 | G19: 0 | H19: 0 | I19: 0 | J19: 0 | K19: 0 | L19: 0 | M19: 1 | N19: 0 | O19: 0 | P19: 0 | Q19: 0 | R19: 0 | T19: =DAY(C19) | U19: =MONTH(C19) | V19: 2025
A20: 45975.487 | B20: Nguyễn Hồng Minh | C20: 45974 | D20: 0 | E20: 0 | F20: 0 | G20: 1 | H20: 1 | I20: 1 | J20: 0 | K20: 15 | L20: 2 | M20: 0 | N20: 1 | O20: 0 | P20: 0 | Q20: 3 | R20: 0 | T20: =DAY(C20) | U20: =MONTH(C20) | V20: 2025
A21: 45975.491 | B21: Nguyễn Văn Nhật | C21: 45974 | D21: 0 | E21: 0 | F21: 0 | G21: 0 | H21: 0 | I21: 0 | J21: 0 | K21: 3 | L21: 2 | M21: 1 | N21: 2 | O21: 0 | P21: 2 | Q21: 5 | R21: 0 | T21: =DAY(C21) | U21: =MONTH(C21) | V21: 2025
A22: 45975.495 | B22: Huỳnh Văn Lực | C22: 45974 | D22: 0 | E22: 0 | F22: 0 | G22: 0 | H22: 0 | I22: 0 | J22: 0 | K22: 4 | L22: 0 | M22: 0 | N22: 0 | O22: 0 | P22: 2 | Q22: 0 | R22: 0 | T22: =DAY(C22) | U22: =MONTH(C22) | V22: 2025
A23: 45975.504 | B23: Bùi Duy Cường | C23: 45974 | D23: 0 | E23: 0 | F23: 0 | G23: 1 | H23: 1 | I23: 2 | J23: 1 | K23: 18 | L23: 0 | M23: 0 | N23: 1 | O23: 1 | P23: 1 | Q23: 3 | R23: 0 | T23: =DAY(C23) | U23: =MONTH(C23) | V23: 2025
A24: 45975.506 | B24: Trần Trung Giang | C24: 45974 | D24: 0 | E24: 0 | F24: 0 | G24: 0 | H24: 0 | I24: 0 | J24: 1 | K24: 6 | L24: 0 | M24: 0 | N24: 1 | O24: 0 | P24: 0 | Q24: 0 | R24: 0 | T24: =DAY(C24) | U24: =MONTH(C24) | V24: 2025
A25: 45975.506 | B25: Trần Xuân Khoa | C25: 45974 | D25: 0 | E25: 0 | F25: 0 | G25: 0 | H25: 0 | I25: 0 | J25: 0 | K25: 5 | L25: 0 | M25: 0 | N25: 0 | O25: 0 | P25: 1 | Q25: 3 | R25: 0 | T25: =DAY(C25) | U25: =MONTH(C25) | V25: 2025
A26: 45975.972 | B26: Trần Minh Khánh | C26: 45975 | D26: 0 | E26: 0 | F26: 0 | G26: 0 | H26: 0 | I26: 0 | J26: 0 | K26: 7 | L26: 0 | M26: 0 | N26: 0 | O26: 0 | P26: 2 | Q26: 4 | R26: 0 | T26: =DAY(C26) | U26: =MONTH(C26) | V26: 2025
A27: 45976.319 | B27: Hồ Xuân Việt | C27: 45975 | D27: 0 | E27: 0 | F27: 0 | G27: 0 | H27: 0 | I27: 0 | J27: 0 | K27: 6 | L27: 0 | M27: 1 | N27: 1 | O27: 0 | P27: 1 | Q27: 6 | R27: 0 | T27: =DAY(C27) | U27: =MONTH(C27) | V27: 2025
A28: 45976.331 | B28: Bùi Duy Cường | C28: 45975 | D28: 0 | E28: 0 | F28: 0 | G28: 0 | H28: 0 | I28: 0 | J28: 0 | K28: 10 | L28: 0 | M28: 1 | N28: 0 | O28: 0 | P28: 0 | Q28: 2 | R28: 0 | T28: =DAY(C28) | U28: =MONTH(C28) | V28: 2025
... A205: 45983.796 | B205: Đặng Hữu Danh | C205: 45983 | D205: 0 | E205: 0 | F205: 0 | G205: 0 | H205: 0 | I205: 2 | J205: 0 | K205: 5 | L205: 0 | M205: 0 | N205: 4 | O205: 0 | P205: 3 | Q205: 5 | R205: 0 | T205: =DAY(C205) | U205: =MONTH(C205) | V205: 2025
A206: 45984.28 | B206: Lê Quốc Duy | C206: 45983 | D206: 0 | E206: 0 | F206: 0 | G206: 0 | I206: 3 | J206: 0 | K206: 2 | L206: 0 | M206: 1 | N206: 0 | O206: 0 | P206: 0 | Q206: 10 | R206: 0 | T206: =DAY(C206) | U206: =MONTH(C206) | V206: 2025
A207: 45984.299 | B207: Trần Trung Giang | C207: 45983 | D207: 0 | E207: 0 | F207: 0 | G207: 1 | H207: 1 | I207: 2 | J207: 0 | K207: 2 | L207: 0 | M207: 0 | N207: 0 | O207: 0 | P207: 1 | Q207: 0 | R207: 0 | T207: =DAY(C207) | U207: =MONTH(C207) | V207: 2025
A208: 45984.303 | B208: Đặng Hoài Anh | C208: 45983 | D208: 0 | E208: 0 | F208: 0 | G208: 0 | H208: 0 | I208: 2 | J208: 0 | K208: 0 | L208: 0 | M208: 1 | N208: 0 | O208: 0 | P208: 2 | Q208: 0 | R208: 0 | T208: =DAY(C208) | U208: =MONTH(C208) | V208: 2025
A209: 45984.307 | B209: Nguyễn Tuấn Anh | C209: 45983 | D209: 1 | E209: 0 | F209: 0 | G209: 0 | H209: 0 | I209: 2 | J209: 0 | K209: 1 | L209: 0 | M209: 0 | N209: 0 | O209: 0 | P209: 1 | Q209: 5 | R209: 0 | T209: =DAY(C209) | U209: =MONTH(C209) | V209: 2025
A210: 45984.31 | B210: Nguyễn Quang Anh Tuấn | C210: 45983 | D210: 0 | E210: 0 | F210: 0 | G210: 0 | H210: 0 | I210: 2 | J210: 0 | K210: 10 | L210: 0 | M210: 0 | N210: 0 | O210: 0 | P210: 1 | Q210: 2 | R210: 0 | T210: =DAY(C210) | U210: =MONTH(C210) | V210: 2025
A211: 45984.313 | B211: Trần Xuân Khoa | C211: 45983 | D211: 0 | E211: 0 | F211: 0 | G211: 0 | H211: 0 | I211: 0 | J211: 0 | K211: 12 | L211: 0 | M211: 0 | N211: 0 | O211: 0 | P211: 0 | Q211: 3 | R211: 0 | T211: =DAY(C211) | U211: =MONTH(C211) | V211: 2025
A212: 45984.333 | B212: Hồ Xuân Việt | C212: 45983 | D212: 0 | E212: 0 | F212: 0 | G212: 0 | I212: 1 | J212: 0 | K212: 10 | L212: 0 | M212: 0 | N212: 1 | O212: 0 | P212: 1 | Q212: 4 | R212: 0 | T212: =DAY(C212) | U212: =MONTH(C212) | V212: 2025
A213: 45984.357 | B213: Nguyễn Văn Hiệp | C213: 45983 | D213: 0 | E213: 0 | F213: 0 | G213: 0 | H213: 0 | I213: 0 | J213: 0 | K213: 5 | L213: 0 | M213: 0 | N213: 0 | O213: 0 | P213: 0 | Q213: 0 | R213: 0 | T213: =DAY(C213) | U213: =MONTH(C213) | V213: 2025
A214: 45984.382 | B214: Lương Duy Hoàng | C214: 45983 | D214: 0 | E214: 0 | F214: 0 | G214: 0 | H214: 0 | I214: 1 | J214: 0 | K214: 7 | L214: 0 | M214: 0 | N214: 0 | O214: 0 | P214: 1 | Q214: 2 | R214: 0 | T214: =DAY(C214) | U214: =MONTH(C214) | V214: 2025
A215: 45984.385 | B215: Bùi Duy Cường | C215: 45983 | D215: 1 | E215: 1 | F215: 0 | G215: 1 | H215: 1 | I215: 1 | J215: 1 | K215: 10 | L215: 0 | M215: 1 | N215: 1 | O215: 0 | P215: 0 | Q215: 2 | R215: 0 | T215: =DAY(C215) | U215: =MONTH(C215) | V215: 2025
A216: 45984.398 | B216: Huỳnh Văn Lực | C216: 45983 | D216: 0 | E216: 0 | F216: 0 | G216: 0 | H216: 0 | I216: 0 | J216: 0 | K216: 8 | L216: 0 | M216: 0 | N216: 0 | O216: 0 | P216: 1 | Q216: 1 | R216: 0 | T216: =DAY(C216) | U216: =MONTH(C216) | V216: 2025
...

Sheet BaoCao_NhapLieu
A1: BÁO CÁO CÔNG TÁC NHẬP LIỆU CỦA NHÂN VIÊN KTĐB
A3: Họ và tên | B3: Năm | C3: Tháng | D3: Tuần | H3: Tổng | I3: Tỉ lệ(%)
A4: =IFERROR(__xludf.DUMMYFUNCTION("QUERY( { DuLieu!B2:B101562, DuLieu!U2:U101562, DuLieu!V2:V101562, ARRAYFORMULA( IF(DuLieu!T2:T101562="""",, IF(DuLieu!T2:T101562<=7, 1, IF(DuLieu!T2:T101562<=14, 2, IF(DuLieu!T2:T101562<=21, 3, 4) "&" ) ) ) ) }, ""select Col1, Col3, Col2, count(Col1) where Col1 is not null and Col1<>'Tổng' group by Col1, Col2, Col3 pivot Col4 order by Col2, Col3, Col1 label count(Col1) ''"", 0 ) "),"#REF!")
H5: =D5+E5+F5+G5 | I5: =H5/30*100
H6: =D6+E6+F6+G6 | I6: =H6/30*100
H7: =D7+E7+F7+G7 | I7: =H7/30*100
H8: =D8+E8+F8+G8 | I8: =H8/30*100
H9: =D9+E9+F9+G9 | I9: =H9/30*100
H10: =D10+E10+F10+G10 | I10: =H10/30*100
H11: =D11+E11+F11+G11 | I11: =H11/30*100
H12: =D12+E12+F12+G12 | I12: =H12/30*100
H13: =D13+E13+F13+G13 | I13: =H13/30*100
H14: =D14+E14+F14+G14 | I14: =H14/30*100
H15: =D15+E15+F15+G15 | I15: =H15/30*100
H16: =D16+E16+F16+G16 | I16: =H16/30*100
... H34: =D34+E34+F34+G34 | I34: =H34/30*100

Sheet Dashboard_TongHop
A1: BÁO CÁO TỔNG HỢP NHÂN SỰ XUÂN LỘC
A2: Ngày cập nhật: | B2: 46114.948
A4: Họ và tên | B4: Bán Fiber | C4: Bán MyTV | D4: Bán Camera | E4: NGHTT | F4: GHTT | G4: Lắp đặt | H4: Sửa chữa | I4: Xử lý Suy hao
A5: Tổng | B5: 477 | C5: 372 | D5: 300 | E5: 9944 | F5: 926 | G5: 830 | H5: 3578 | I5: 1181
A6: Trần Trung Giang | B6: 20 | C6: 14 | D6: 27 | E6: 415 | F6: 7 | G6: 46 | H6: 48 | I6: 58
A7: Lương Duy Hoàng | B7: 9 | C7: 7 | D7: 11 | E7: 317 | F7: 17 | G7: 30 | H7: 166 | I7: 34
A8: Hồ Thái Minh Trí | B8: 6 | C8: 3 | D8: 6 | E8: 409 | F8: 55 | G8: 24 | H8: 91 | I8: 6
A9: Lê Văn Hồng | B9: 16 | C9: 6 | D9: 0 | E9: 245 | F9: 44 | G9: 35 | H9: 139 | I9: 88
A10: Lê Quốc Duy | B10: 6 | C10: 4 | D10: 3 | E10: 318 | F10: 38 | G10: 19 | H10: 128 | I10: 37
A11: Vòng Nhật Sang | B11: 13 | C11: 3 | D11: 2 | E11: 642 | F11: 26 | G11: 30 | H11: 157 | I11: 117
A12: Nguyễn Tuấn Anh | B12: 65 | C12: 29 | D12: 25 | E12: 1162 | F12: 77 | G12: 0 | H12: 434 | I12: 70
A13: Dương Minh Tiến | B13: 10 | C13: 10 | D13: 4 | E13: 493 | F13: 42 | G13: 31 | H13: 35 | I13: 26
A14: Phan Thành Thái | B14: 15 | C14: 16 | D14: 9 | E14: 362 | F14: 27 | G14: 29 | H14: 217 | I14: 38
A15: Đặng Hoài Anh | B15: 35 | C15: 26 | D15: 15 | E15: 264 | F15: 15 | G15: 66 | H15: 55 | I15: 54
A16: Nguyễn Quang Anh Tuấn | B16: 21 | C16: 14 | D16: 8 | E16: 471 | F16: 30 | G16: 68 | H16: 160 | I16: 28
... A31: Hoàng Văn Chất | B31: 4 | C31: 1 | D31: 1 | E31: 145 | F31: 27 | G31: 9 | H31: 25 | I31: 4

Sheet Ngay
A1: Ngày | B1: Tiếp thị DV Fiber | C1: Tiếp thị DV MyTV | D1: Tiếp thị DV Camera/Mesh | E1: Tạm ngưng Fiber | F1: Tạm ngưng Mytv | G1: Thay thế ONT 2 băng tần | H1: CSKH HVC chuyển XGSPON | I1: Phiếu GHTT tháng T | J1: Phiếu GHTT tháng T+1 | K1: Lắp đặt/ dịch chuyển | L1: Thu hồi TBĐC (ONT) | M1: Thu hồi TBĐC (Mesh) | N1: Xử lý phiếu chủ động BRCD | O1: Sửa chữa máy hỏng | P1: B2A có nguy cơ rời mạng | Q1: Tháng | R1: Nam
A2: Tổng | B2: =SUM(B3:B33) | C2: =SUM(C3:C33) | D2: =SUM(D3:D33) | E2: =SUM(E3:E33) | F2: =SUM(F3:F33) | G2: =SUM(G3:G33) | H2: =SUM(H3:H33) | I2: =SUM(I3:I33) | ... P2: =SUM(P3:P33)
A3: 1 | B3: =SUMIFS(DuLieu!$D$3:$D$101908,DuLieu!$T$3:$T$101928,A3,DuLieu!$U$3:$U$101928,Q3) | C3: =SUMIFS(DuLieu!$E$3:$E$101908,DuLieu!$T$3:$T$101908,A3,DuLieu!$U$3:$U$101908,Q3) | D3: =SUMIFS(DuLieu!$F$3:$F$101908,DuLieu!$T$3:$T$1001908,A3,DuLieu!$U$3:$U$101908,Q3) | E3: =SUMIFS(DuLieu!$G$3:$G$101908,DuLieu!$T$3:$T$101908,A3,DuLieu!$U$3:$U$101908,Q3) | F3: =SUMIFS(DuLieu!$H$3:$H$101908,DuLieu!$T$3:$T$101908,A3,DuLieu!$U$3:$U$101908,Q3) | G3: =SUMIFS(DuLieu!$I$3:$I$11908,DuLieu!$T$3:$T$101908,A3,DuLieu!$U$3:$U$101908,Q3) | H3: =SUMIFS(DuLieu!$J$3:$J$101908,DuLieu!$T$3:$T$101908,A3,DuLieu!$U$3:$U$101908,Q3) | I3: =SUMIFS(DuLieu!$K$3:$K$101908,DuLieu!$T$3:$T$101908,A3,DuLieu!$U$3:$U$101908,Q3) | J3: =SUMIFS(DuLieu!$L$3:$L$101908,DuLieu!$T$3:$T$101908,A3,DuLieu!$U$3:$U$101908,Q3) | K3: =SUMIFS(DuLieu!$M$3:$M$101908,DuLieu!$T$3:$T$101908,A3,DuLieu!$U$3:$U$101908,Q3) | L3: =SUMIFS(DuLieu!$N$3:$N$101908,DuLieu!$T$3:$T$101908,A3,DuLieu!$U$3:$U$101908,Q3) | M3: =SUMIFS(DuLieu!$O$3:$O$101908,DuLieu!$T$3:$T$101908,A3,DuLieu!$U$3:$U$101908,Q3) | N3: =SUMIFS(DuLieu!$P$3:$P$101908,DuLieu!$T$3:$T$101908,A3,DuLieu!$U$3:$U$101908,Q3) | O3: =SUMIFS(DuLieu!$Q$3:$Q$101908,DuLieu!$T$3:$T$101908,A3,DuLieu!$U$3:$U$101908,Q3) | P3: =SUMIFS(DuLieu!$R$3:$R$101908,DuLieu!$T$3:$T$101908,A3,DuLieu!$U$3:$U$101908,Q3) | Q3: 11 | R3: 2025
A4: 2 | B4: =SUMIFS(DuLieu!$D$3:$D$101908,DuLieu!$T$3:$T$101928,A4,DuLieu!$U$3:$U$101928,Q4) | C4: =SUMIFS(DuLieu!$E$3:$E$101908,DuLieu!$T$3:$T$101908,A4,DuLieu!$U$3:$U$101908,Q4) | D4: =SUMIFS(DuLieu!$F$3:$F$101908,DuLieu!$T$3:$T$1001908,A4,DuLieu!$U$3:$U$101908,Q4) | E4: =SUMIFS(DuLieu!$G$3:$G$101908,DuLieu!$T$3:$T$101908,A4,DuLieu!$U$3:$U$101908,Q4) | F4: =SUMIFS(DuLieu!$H$3:$H$101908,DuLieu!$T$3:$T$101908,A4,DuLieu!$U$3:$U$101908,Q4) | G4: =SUMIFS(DuLieu!$I$3:$I$11908,DuLieu!$T$3:$T$101908,A4,DuLieu!$U$3:$U$101908,Q4) | H4: =SUMIFS(DuLieu!$J$3:$J$101908,DuLieu!$T$3:$T$101908,A4,DuLieu!$U$3:$U$101908,Q4) | I4: =SUMIFS(DuLieu!$K$3:$K$101908,DuLieu!$T$3:$T$101908,A4,DuLieu!$U$3:$U$101908,Q4) | J4: =SUMIFS(DuLieu!$L$3:$L$101908,DuLieu!$T$3:$T$101908,A4,DuLieu!$U$3:$U$101908,Q4) | K4: =SUMIFS(DuLieu!$M$3:$M$101908,DuLieu!$T$3:$T$101908,A4,DuLieu!$U$3:$U$101908,Q4) | L4: =SUMIFS(DuLieu!$N$3:$N$101908,DuLieu!$T$3:$T$101908,A4,DuLieu!$U$3:$U$101908,Q4) | M4: =SUMIFS(DuLieu!$O$3:$O$101908,DuLieu!$T$3:$T$101908,A4,DuLieu!$U$3:$U$101908,Q4) | N4: =SUMIFS(DuLieu!$P$3:$P$101908,DuLieu!$T$3:$T$101908,A4,DuLieu!$U$3:$U$101908,Q4) | O4: =SUMIFS(DuLieu!$Q$3:$Q$101908,DuLieu!$T$3:$T$101908,A4,DuLieu!$U$3:$U$101908,Q4) | P4: =SUMIFS(DuLieu!$R$3:$R$101908,DuLieu!$T$3:$T$101908,A4,DuLieu!$U$3:$U$101908,Q4) | Q4: 11 | R4: 2025
A5: 3 | B5: =SUMIFS(DuLieu!$D$3:$D$101908,DuLieu!$T$3:$T$101928,A5,DuLieu!$U$3:$U$101928,Q5) | C5: =SUMIFS(DuLieu!$E$3:$E$101908,DuLieu!$T$3:$T$101908,A5,DuLieu!$U$3:$U$101908,Q5) | D5: =SUMIFS(DuLieu!$F$3:$F$101908,DuLieu!$T$3:$T$1001908,A5,DuLieu!$U$3:$U$101908,Q5) | E5: =SUMIFS(DuLieu!$G$3:$G$101908,DuLieu!$T$3:$T$101908,A5,DuLieu!$U$3:$U$101908,Q5) | F5: =SUMIFS(DuLieu!$H$3:$H$101908,DuLieu!$T$3:$T$101908,A5,DuLieu!$U$3:$U$101908,Q5) | G5: =SUMIFS(DuLieu!$I$3:$I$11908,DuLieu!$T$3:$T$101908,A5,DuLieu!$U$3:$U$101908,Q5) | H5: =SUMIFS(DuLieu!$J$3:$J$101908,DuLieu!$T$3:$T$101908,A5,DuLieu!$U$3:$U$101908,Q5) | I5: =SUMIFS(DuLieu!$K$3:$K$101908,DuLieu!$T$3:$T$101908,A5,DuLieu!$U$3:$U$101908,Q5) | J5: =SUMIFS(DuLieu!$L$3:$L$101908,DuLieu!$T$3:$T$101908,A5,DuLieu!$U$3:$U$101908,Q5) | K5: =SUMIFS(DuLieu!$M$3:$M$101908,DuLieu!$T$3:$T$101908,A5,DuLieu!$U$3:$U$101908,Q5) | L5: =SUMIFS(DuLieu!$N$3:$N$101908,DuLieu!$T$3:$T$101908,A5,DuLieu!$U$3:$U$101908,Q5) | M5: =SUMIFS(DuLieu!$O$3:$O$101908,DuLieu!$T$3:$T$101908,A5,DuLieu!$U$3:$U$101908,Q5) | N5: =SUMIFS(DuLieu!$P$3:$P$101908,DuLieu!$T$3:$T$101908,A5,DuLieu!$U$3:$U$101908,Q5) | O5: =SUMIFS(DuLieu!$Q$3:$Q$101908,DuLieu!$T$3:$T$101908,A5,DuLieu!$U$3:$U$101908,Q5) | P5: =SUMIFS(DuLieu!$R$3:$R$101908,DuLieu!$T$3:$T$101908,A5,DuLieu!$U$3:$U$101908,Q5) | Q5: 11 | R5: 2025
A6: 4 | B6: =SUMIFS(DuLieu!$D$3:$D$101908,DuLieu!$T$3:$T$101928,A6,DuLieu!$U$3:$U$101928,Q6) | C6: =SUMIFS(DuLieu!$E$3:$E$101908,DuLieu!$T$3:$T$101908,A6,DuLieu!$U$3:$U$101908,Q6) | D6: =SUMIFS(DuLieu!$F$3:$F$101908,DuLieu!$T$3:$T$1001908,A6,DuLieu!$U$3:$U$101908,Q6) | E6: =SUMIFS(DuLieu!$G$3:$G$101908,DuLieu!$T$3:$T$101908,A6,DuLieu!$U$3:$U$101908,Q6) | F6: =SUMIFS(DuLieu!$H$3:$H$101908,DuLieu!$T$3:$T$101908,A6,DuLieu!$U$3:$U$101908,Q6) | G6: =SUMIFS(DuLieu!$I$3:$I$11908,DuLieu!$T$3:$T$101908,A6,DuLieu!$U$3:$U$101908,Q6) | H6: =SUMIFS(DuLieu!$J$3:$J$101908,DuLieu!$T$3:$T$101908,A6,DuLieu!$U$3:$U$101908,Q6) | I6: =SUMIFS(DuLieu!$K$3:$K$101908,DuLieu!$T$3:$T$101908,A6,DuLieu!$U$3:$U$101908,Q6) | J6: =SUMIFS(DuLieu!$L$3:$L$101908,DuLieu!$T$3:$T$101908,A6,DuLieu!$U$3:$U$101908,Q6) | K6: =SUMIFS(DuLieu!$M$3:$M$101908,DuLieu!$T$3:$T$101908,A6,DuLieu!$U$3:$U$101908,Q6) | L6: =SUMIFS(DuLieu!$N$3:$N$101908,DuLieu!$T$3:$T$101908,A6,DuLieu!$U$3:$U$101908,Q6) | M6: =SUMIFS(DuLieu!$O$3:$O$101908,DuLieu!$T$3:$T$101908,A6,DuLieu!$U$3:$U$101908,Q6) | N6: =SUMIFS(DuLieu!$P$3:$P$101908,DuLieu!$T$3:$T$101908,A6,DuLieu!$U$3:$U$101908,Q6) | O6: =SUMIFS(DuLieu!$Q$3:$Q$101908,DuLieu!$T$3:$T$101908,A6,DuLieu!$U$3:$U$101908,Q6) | P6: =SUMIFS(DuLieu!$R$3:$R$101908,DuLieu!$T$3:$T$101908,A6,DuLieu!$U$3:$U$101908,Q6) | Q6: 11 | R6: 2025
A7: 5 | B7: =SUMIFS(DuLieu!$D$3:$D$101908,DuLieu!$T$3:$T$101928,A7,DuLieu!$U$3:$U$101928,Q7) | C7: =SUMIFS(DuLieu!$E$3:$E$101908,DuLieu!$T$3:$T$101908,A7,DuLieu!$U$3:$U$101908,Q7) | D7: =SUMIFS(DuLieu!$F$3:$F$101908,DuLieu!$T$3:$T$1001908,A7,DuLieu!$U$3:$U$101908,Q7) | E7: =SUMIFS(DuLieu!$G$3:$G$101908,DuLieu!$T$3:$T$101908,A7,DuLieu!$U$3:$U$101908,Q7) | F7: =SUMIFS(DuLieu!$H$3:$H$101908,DuLieu!$T$3:$T$101908,A7,DuLieu!$U$3:$U$101908,Q7) | G7: =SUMIFS(DuLieu!$I$3:$I$11908,DuLieu!$T$3:$T$101908,A7,DuLieu!$U$3:$U$101908,Q7) | H7: =SUMIFS(DuLieu!$J$3:$J$101908,DuLieu!$T$3:$T$101908,A7,DuLieu!$U$3:$U$101908,Q7) | I7: =SUMIFS(DuLieu!$K$3:$K$101908,DuLieu!$T$3:$T$101908,A7,DuLieu!$U$3:$U$101908,Q7) | J7: =SUMIFS(DuLieu!$L$3:$L$101908,DuLieu!$T$3:$T$101908,A7,DuLieu!$U$3:$U$101908,Q7) | K7: =SUMIFS(DuLieu!$M$3:$M$101908,DuLieu!$T$3:$T$101908,A7,DuLieu!$U$3:$U$101908,Q7) | L7: =SUMIFS(DuLieu!$N$3:$N$101908,DuLieu!$T$3:$T$101908,A7,DuLieu!$U$3:$U$101908,Q7) | M7: =SUMIFS(DuLieu!$O$3:$O$101908,DuLieu!$T$3:$T$101908,A7,DuLieu!$U$3:$U$101908,Q7) | N7: =SUMIFS(DuLieu!$P$3:$P$101908,DuLieu!$T$3:$T$101908,A7,DuLieu!$U$3:$U$101908,Q7) | O7: =SUMIFS(DuLieu!$Q$3:$Q$101908,DuLieu!$T$3:$T$101908,A7,DuLieu!$U$3:$U$101908,Q7) | P7: =SUMIFS(DuLieu!$R$3:$R$101908,DuLieu!$T$3:$T$101908,A7,DuLieu!$U$3:$U$101908,Q7) | Q7: 11 | R7: 2025
A8: 6 | B8: =SUMIFS(DuLieu!$D$3:$D$101908,DuLieu!$T$3:$T$101928,A8,DuLieu!$U$3:$U$101928,Q8) | C8: =SUMIFS(DuLieu!$E$3:$E$101908,DuLieu!$T$3:$T$101908,A8,DuLieu!$U$3:$U$101908,Q8) | D8: =SUMIFS(DuLieu!$F$3:$F$101908,DuLieu!$T$3:$T$1001908,A8,DuLieu!$U$3:$U$101908,Q8) | E8: =SUMIFS(DuLieu!$G$3:$G$101908,DuLieu!$T$3:$T$101908,A8,DuLieu!$U$3:$U$101908,Q8) | F8: =SUMIFS(DuLieu!$H$3:$H$101908,DuLieu!$T$3:$T$101908,A8,DuLieu!$U$3:$U$101908,Q8) | G8: =SUMIFS(DuLieu!$I$3:$I$11908,DuLieu!$T$3:$T$101908,A8,DuLieu!$U$3:$U$101908,Q8) | H8: =SUMIFS(DuLieu!$J$3:$J$101908,DuLieu!$T$3:$T$101908,A8,DuLieu!$U$3:$U$101908,Q8) | I8: =SUMIFS(DuLieu!$K$3:$K$101908,DuLieu!$T$3:$T$101908,A8,DuLieu!$U$3:$U$101908,Q8) | J8: =SUMIFS(DuLieu!$L$3:$L$101908,DuLieu!$T$3:$T$101908,A8,DuLieu!$U$3:$U$101908,Q8) | K8: =SUMIFS(DuLieu!$M$3:$M$101908,DuLieu!$T$3:$T$101908,A8,DuLieu!$U$3:$U$101908,Q8) | L8: =SUMIFS(DuLieu!$N$3:$N$101908,DuLieu!$T$3:$T$101908,A8,DuLieu!$U$3:$U$101908,Q8) | M8: =SUMIFS(DuLieu!$O$3:$O$101908,DuLieu!$T$3:$T$101908,A8,DuLieu!$U$3:$U$101908,Q8) | N8: =SUMIFS(DuLieu!$P$3:$P$101908,DuLieu!$T$3:$T$101908,A8,DuLieu!$U$3:$U$101908,Q8) | O8: =SUMIFS(DuLieu!$Q$3:$Q$101908,DuLieu!$T$3:$T$101908,A8,DuLieu!$U$3:$U$101908,Q8) | P8: =SUMIFS(DuLieu!$R$3:$R$101908,DuLieu!$T$3:$T$101908,A8,DuLieu!$U$3:$U$101908,Q8) | Q8: 11 | R8: 2025
A9: 7 | B9: =SUMIFS(DuLieu!$D$3:$D$101908,DuLieu!$T$3:$T$101928,A9,DuLieu!$U$3:$U$101928,Q9) | C9: =SUMIFS(DuLieu!$E$3:$E$101908,DuLieu!$T$3:$T$101908,A9,DuLieu!$U$3:$U$101908,Q9) | D9: =SUMIFS(DuLieu!$F$3:$F$101908,DuLieu!$T$3:$T$1001908,A9,DuLieu!$U$3:$U$101908,Q9) | E9: =SUMIFS(DuLieu!$G$3:$G$101908,DuLieu!$T$3:$T$101908,A9,DuLieu!$U$3:$U$101908,Q9) | F9: =SUMIFS(DuLieu!$H$3:$H$101908,DuLieu!$T$3:$T$101908,A9,DuLieu!$U$3:$U$101908,Q9) | G9: =SUMIFS(DuLieu!$I$3:$I$11908,DuLieu!$T$3:$T$101908,A9,DuLieu!$U$3:$U$101908,Q9) | H9: =SUMIFS(DuLieu!$J$3:$J$101908,DuLieu!$T$3:$T$101908,A9,DuLieu!$U$3:$U$101908,Q9) | I9: =SUMIFS(DuLieu!$K$3:$K$101908,DuLieu!$T$3:$T$101908,A9,DuLieu!$U$3:$U$101908,Q9) | J9: =SUMIFS(DuLieu!$L$3:$L$101908,DuLieu!$T$3:$T$101908,A9,DuLieu!$U$3:$U$101908,Q9) | K9: =SUMIFS(DuLieu!$M$3:$M$101908,DuLieu!$T$3:$T$101908,A9,DuLieu!$U$3:$U$101908,Q9) | L9: =SUMIFS(DuLieu!$N$3:$N$101908,DuLieu!$T$3:$T$101908,A9,DuLieu!$U$3:$U$101908,Q9) | M9: =SUMIFS(DuLieu!$O$3:$O$101908,DuLieu!$T$3:$T$101908,A9,DuLieu!$U$3:$U$101908,Q9) | N9: =SUMIFS(DuLieu!$P$3:$P$101908,DuLieu!$T$3:$T$101908,A9,DuLieu!$U$3:$U$101908,Q9) | O9: =SUMIFS(DuLieu!$Q$3:$Q$101908,DuLieu!$T$3:$T$101908,A9,DuLieu!$U$3:$U$101908,Q9) | P9: =SUMIFS(DuLieu!$R$3:$R$101908,DuLieu!$T$3:$T$101908,A9,DuLieu!$U$3:$U$101908,Q9) | Q9: 11 | R9: 2025
A10: 8 | B10: =SUMIFS(DuLieu!$D$3:$D$101908,DuLieu!$T$3:$T$101928,A10,DuLieu!$U$3:$U$101928,Q10) | C10: =SUMIFS(DuLieu!$E$3:$E$101908,DuLieu!$T$3:$T$101908,A10,DuLieu!$U$3:$U$101908,Q10) | D10: =SUMIFS(DuLieu!$F$3:$F$101908,DuLieu!$T$3:$T$1001908,A10,DuLieu!$U$3:$U$101908,Q10) | E10: =SUMIFS(DuLieu!$G$3:$G$101908,DuLieu!$T$3:$T$101908,A10,DuLieu!$U$3:$U$101908,Q10) | F10: =SUMIFS(DuLieu!$H$3:$H$101908,DuLieu!$T$3:$T$101908,A10,DuLieu!$U$3:$U$101908,Q10) | G10: =SUMIFS(DuLieu!$I$3:$I$11908,DuLieu!$T$3:$T$101908,A10,DuLieu!$U$3:$U$101908,Q10) | H10: =SUMIFS(DuLieu!$J$3:$J$101908,DuLieu!$T$3:$T$101908,A10,DuLieu!$U$3:$U$101908,Q10) | I10: =SUMIFS(DuLieu!$K$3:$K$101908,DuLieu!$T$3:$T$101908,A10,DuLieu!$U$3:$U$101908,Q10) | J10: =SUMIFS(DuLieu!$L$3:$L$101908,DuLieu!$T$3:$T$101908,A10,DuLieu!$U$3:$U$101908,Q10) | K10: =SUMIFS(DuLieu!$M$3:$M$101908,DuLieu!$T$3:$T$101908,A10,DuLieu!$U$3:$U$101908,Q10) | L10: =SUMIFS(DuLieu!$N$3:$N$101908,DuLieu!$T$3:$T$101908,A10,DuLieu!$U$3:$U$101908,Q10) | M10: =SUMIFS(DuLieu!$O$3:$O$101908,DuLieu!$T$3:$T$101908,A10,DuLieu!$U$3:$U$101908,Q10) | N10: =SUMIFS(DuLieu!$P$3:$P$101908,DuLieu!$T$3:$T$101908,A10,DuLieu!$U$3:$U$101908,Q10) | O10: =SUMIFS(DuLieu!$Q$3:$Q$101908,DuLieu!$T$3:$T$101908,A10,DuLieu!$U$3:$U$101908,Q10) | P10: =SUMIFS(DuLieu!$R$3:$R$101908,DuLieu!$T$3:$T$101908,A10,DuLieu!$U$3:$U$101908,Q10) | Q10: 11 | R10: 2025
A11: 9 | B11: =SUMIFS(DuLieu!$D$3:$D$101908,DuLieu!$T$3:$T$101928,A11,DuLieu!$U$3:$U$101928,Q11) | C11: =SUMIFS(DuLieu!$E$3:$E$101908,DuLieu!$T$3:$T$101908,A11,DuLieu!$U$3:$U$101908,Q11) | D11: =SUMIFS(DuLieu!$F$3:$F$101908,DuLieu!$T$3:$T$1001908,A11,DuLieu!$U$3:$U$101908,Q11) | E11: =SUMIFS(DuLieu!$G$3:$G$101908,DuLieu!$T$3:$T$101908,A11,DuLieu!$U$3:$U$101908,Q11) | F11: =SUMIFS(DuLieu!$H$3:$H$101908,DuLieu!$T$3:$T$101908,A11,DuLieu!$U$3:$U$101908,Q11) | G11: =SUMIFS(DuLieu!$I$3:$I$11908,DuLieu!$T$3:$T$101908,A11,DuLieu!$U$3:$U$101908,Q11) | H11: =SUMIFS(DuLieu!$J$3:$J$101908,DuLieu!$T$3:$T$101908,A11,DuLieu!$U$3:$U$101908,Q11) | I11: =SUMIFS(DuLieu!$K$3:$K$101908,DuLieu!$T$3:$T$101908,A11,DuLieu!$U$3:$U$101908,Q11) | J11: =SUMIFS(DuLieu!$L$3:$L$101908,DuLieu!$T$3:$T$101908,A11,DuLieu!$U$3:$U$101908,Q11) | K11: =SUMIFS(DuLieu!$M$3:$M$101908,DuLieu!$T$3:$T$101908,A11,DuLieu!$U$3:$U$101908,Q11) | L11: =SUMIFS(DuLieu!$N$3:$N$101908,DuLieu!$T$3:$T$101908,A11,DuLieu!$U$3:$U$101908,Q11) | M11: =SUMIFS(DuLieu!$O$3:$O$101908,DuLieu!$T$3:$T$101908,A11,DuLieu!$U$3:$U$101908,Q11) | N11: =SUMIFS(DuLieu!$P$3:$P$101908,DuLieu!$T$3:$T$101908,A11,DuLieu!$U$3:$U$101908,Q11) | O11: =SUMIFS(DuLieu!$Q$3:$Q$101908,DuLieu!$T$3:$T$101908,A11,DuLieu!$U$3:$U$101908,Q11) | P11: =SUMIFS(DuLieu!$R$3:$R$101908,DuLieu!$T$3:$T$101908,A11,DuLieu!$U$3:$U$101908,Q11) | Q11: 11 | R11: 2025
A12: 10 | B12: =SUMIFS(DuLieu!$D$3:$D$101908,DuLieu!$T$3:$T$101928,A12,DuLieu!$U$3:$U$101928,Q12) | C12: =SUMIFS(DuLieu!$E$3:$E$101908,DuLieu!$T$3:$T$101908,A12,DuLieu!$U$3:$U$101908,Q12) | D12: =SUMIFS(DuLieu!$F$3:$F$101908,DuLieu!$T$3:$T$1001908,A12,DuLieu!$U$3:$U$101908,Q12) | E12: =SUMIFS(DuLieu!$G$3:$G$101908,DuLieu!$T$3:$T$101908,A12,DuLieu!$U$3:$U$101908,Q12) | F12: =SUMIFS(DuLieu!$H$3:$H$101908,DuLieu!$T$3:$T$101908,A12,DuLieu!$U$3:$U$101908,Q12) | G12: =SUMIFS(DuLieu!$I$3:$I$11908,DuLieu!$T$3:$T$101908,A12,DuLieu!$U$3:$U$101908,Q12) | H12: =SUMIFS(DuLieu!$J$3:$J$101908,DuLieu!$T$3:$T$101908,A12,DuLieu!$U$3:$U$101908,Q12) | I12: =SUMIFS(DuLieu!$K$3:$K$101908,DuLieu!$T$3:$T$101908,A12,DuLieu!$U$3:$U$101908,Q12) | J12: =SUMIFS(DuLieu!$L$3:$L$101908,DuLieu!$T$3:$T$101908,A12,DuLieu!$U$3:$U$101908,Q12) | K12: =SUMIFS(DuLieu!$M$3:$M$101908,DuLieu!$T$3:$T$101908,A12,DuLieu!$U$3:$U$101908,Q12) | L12: =SUMIFS(DuLieu!$N$3:$N$101908,DuLieu!$T$3:$T$101908,A12,DuLieu!$U$3:$U$101908,Q12) | M12: =SUMIFS(DuLieu!$O$3:$O$101908,DuLieu!$T$3:$T$101908,A12,DuLieu!$U$3:$U$101908,Q12) | N12: =SUMIFS(DuLieu!$P$3:$P$101908,DuLieu!$T$3:$T$101908,A12,DuLieu!$U$3:$U$101908,Q12) | O12: =SUMIFS(DuLieu!$Q$3:$Q$101908,DuLieu!$T$3:$T$101908,A12,DuLieu!$U$3:$U$101908,Q12) | P12: =SUMIFS(DuLieu!$R$3:$R$101908,DuLieu!$T$3:$T$101908,A12,DuLieu!$U$3:$U$101908,Q12) | Q12: 11 | R12: 2025
A13: 11 | B13: =SUMIFS(DuLieu!$D$3:$D$101908,DuLieu!$T$3:$T$101928,A13,DuLieu!$U$3:$U$101928,Q13) | C13: =SUMIFS(DuLieu!$E$3:$E$101908,DuLieu!$T$3:$T$101908,A13,DuLieu!$U$3:$U$101908,Q13) | D13: =SUMIFS(DuLieu!$F$3:$F$101908,DuLieu!$T$3:$T$1001908,A13,DuLieu!$U$3:$U$101908,Q13) | E13: =SUMIFS(DuLieu!$G$3:$G$101908,DuLieu!$T$3:$T$101908,A13,DuLieu!$U$3:$U$101908,Q13) | F13: =SUMIFS(DuLieu!$H$3:$H$101908,DuLieu!$T$3:$T$101908,A13,DuLieu!$U$3:$U$101908,Q13) | G13: =SUMIFS(DuLieu!$I$3:$I$11908,DuLieu!$T$3:$T$101908,A13,DuLieu!$U$3:$U$101908,Q13) | H13: =SUMIFS(DuLieu!$J$3:$J$101908,DuLieu!$T$3:$T$101908,A13,DuLieu!$U$3:$U$101908,Q13) | I13: =SUMIFS(DuLieu!$K$3:$K$101908,DuLieu!$T$3:$T$101908,A13,DuLieu!$U$3:$U$101908,Q13) | J13: =SUMIFS(DuLieu!$L$3:$L$101908,DuLieu!$T$3:$T$101908,A13,DuLieu!$U$3:$U$101908,Q13) | K13: =SUMIFS(DuLieu!$M$3:$M$101908,DuLieu!$T$3:$T$101908,A13,DuLieu!$U$3:$U$101908,Q13) | L13: =SUMIFS(DuLieu!$N$3:$N$101908,DuLieu!$T$3:$T$101908,A13,DuLieu!$U$3:$U$101908,Q13) | M13: =SUMIFS(DuLieu!$O$3:$O$101908,DuLieu!$T$3:$T$101908,A13,DuLieu!$U$3:$U$101908,Q13) | N13: =SUMIFS(DuLieu!$P$3:$P$101908,DuLieu!$T$3:$T$101908,A13,DuLieu!$U$3:$U$101908,Q13) | O13: =SUMIFS(DuLieu!$Q$3:$Q$101908,DuLieu!$T$3:$T$101908,A13,DuLieu!$U$3:$U$101908,Q13) | P13: =SUMIFS(DuLieu!$R$3:$R$101908,DuLieu!$T$3:$T$101908,A13,DuLieu!$U$3:$U$101908,Q13) | Q13: 11 | R13: 2025
A14: 12 | B14: =SUMIFS(DuLieu!$D$3:$D$101908,DuLieu!$T$3:$T$101928,A14,DuLieu!$U$3:$U$101928,Q14) | C14: =SUMIFS(DuLieu!$E$3:$E$101908,DuLieu!$T$3:$T$101908,A14,DuLieu!$U$3:$U$101908,Q14) | D14: =SUMIFS(DuLieu!$F$3:$F$101908,DuLieu!$T$3:$T$1001908,A14,DuLieu!$U$3:$U$101908,Q14) | E14: =SUMIFS(DuLieu!$G$3:$G$101908,DuLieu!$T$3:$T$101908,A14,DuLieu!$U$3:$U$101908,Q14) | F14: =SUMIFS(DuLieu!$H$3:$H$101908,DuLieu!$T$3:$T$101908,A14,DuLieu!$U$3:$U$101908,Q14) | G14: =SUMIFS(DuLieu!$I$3:$I$11908,DuLieu!$T$3:$T$101908,A14,DuLieu!$U$3:$U$101908,Q14) | H14: =SUMIFS(DuLieu!$J$3:$J$101908,DuLieu!$T$3:$T$101908,A14,DuLieu!$U$3:$U$101908,Q14) | I14: =SUMIFS(DuLieu!$K$3:$K$101908,DuLieu!$T$3:$T$101908,A14,DuLieu!$U$3:$U$101908,Q14) | J14: =SUMIFS(DuLieu!$L$3:$L$101908,DuLieu!$T$3:$T$101908,A14,DuLieu!$U$3:$U$101908,Q14) | K14: =SUMIFS(DuLieu!$M$3:$M$101908,DuLieu!$T$3:$T$101908,A14,DuLieu!$U$3:$U$101908,Q14) | L14: =SUMIFS(DuLieu!$N$3:$N$101908,DuLieu!$T$3:$T$101908,A14,DuLieu!$U$3:$U$101908,Q14) | M14: =SUMIFS(DuLieu!$O$3:$O$101908,DuLieu!$T$3:$T$101908,A14,DuLieu!$U$3:$U$101908,Q14) | N14: =SUMIFS(DuLieu!$P$3:$P$101908,DuLieu!$T$3:$T$101908,A14,DuLieu!$U$3:$U$101908,Q14) | O14: =SUMIFS(DuLieu!$Q$3:$Q$101908,DuLieu!$T$3:$T$101908,A14,DuLieu!$U$3:$U$101908,Q14) | P14: =SUMIFS(DuLieu!$R$3:$R$101908,DuLieu!$T$3:$T$101908,A14,DuLieu!$U$3:$U$101908,Q14) | Q14: 11 | R14: 2025
... A95: 31 | B95: =SUMIFS(DuLieu!$D$3:$D$101908,DuLieu!$T$3:$T$101928,A95,DuLieu!$U$3:$U$101928,Q95) | C95: =SUMIFS(DuLieu!$E$3:$E$101908,DuLieu!$T$3:$T$101908,A95,DuLieu!$U$3:$U$101908,Q95) | D95: =SUMIFS(DuLieu!$F$3:$F$101908,DuLieu!$T$3:$T$1001908,A95,DuLieu!$U$3:$U$101908,Q95) | E95: =SUMIFS(DuLieu!$G$3:$G$101908,DuLieu!$T$3:$T$101908,A95,DuLieu!$U$3:$U$101908,Q95) | F95: =SUMIFS(DuLieu!$H$3:$H$101908,DuLieu!$T$3:$T$101908,A95,DuLieu!$U$3:$U$101908,Q95) | G95: =SUMIFS(DuLieu!$I$3:$I$11908,DuLieu!$T$3:$T$101908,A95,DuLieu!$U$3:$U$101908,Q95) | H95: =SUMIFS(DuLieu!$J$3:$J$101908,DuLieu!$T$3:$T$101908,A95,DuLieu!$U$3:$U$101908,Q95) | I95: =SUMIFS(DuLieu!$K$3:$K$101908,DuLieu!$T$3:$T$101908,A95,DuLieu!$U$3:$U$101908,Q95) | J95: =SUMIFS(DuLieu!$L$3:$L$101908,DuLieu!$T$3:$T$101908,A95,DuLieu!$U$3:$U$101908,Q95) | K95: =SUMIFS(DuLieu!$M$3:$M$101908,DuLieu!$T$3:$T$101908,A95,DuLieu!$U$3:$U$101908,Q95) | L95: =SUMIFS(DuLieu!$N$3:$N$101908,DuLieu!$T$3:$T$101908,A95,DuLieu!$U$3:$U$101908,Q95) | M95: =SUMIFS(DuLieu!$O$3:$O$101908,DuLieu!$T$3:$T$101908,A95,DuLieu!$U$3:$U$101908,Q95) | N95: =SUMIFS(DuLieu!$P$3:$P$101908,DuLieu!$T$3:$T$101908,A95,DuLieu!$U$3:$U$101908,Q95) | O95: =SUMIFS(DuLieu!$Q$3:$Q$101908,DuLieu!$T$3:$T$101908,A95,DuLieu!$U$3:$U$101908,Q95) | P95: =SUMIFS(DuLieu!$R$3:$R$101908,DuLieu!$T$3:$T$101908,A95,DuLieu!$U$3:$U$101908,Q95) | Q95: 1 | R95: 2026

Sheet Tuan
B1: Mục tiêu | C1: Tuần 1 | F1: Tuần 2 | I1: Tuần 3 | L1: Tuần 4 | O1: Tháng
C2: KH giao | D2: Thực hiện | E2: Còn lại | F2: KH giao | G2: Thực hiện | H2: Còn lại | I2: KH giao | J2: Thực hiện | K2: Còn lại | L2: KH giao | M2: Thực hiện | N2: Còn lại | O2: KH giao | P2: Thực hiện | Q2: Còn lại | R2: Thang | S2: Nam
A3: TTVT Xuân Lộc | B3: Tiếp thị DV Fiber | C3: 1 | D3: =SUMIFS(Ngay!$B$3:$B$100000,Ngay!$A$3:$A$100000,">=1",Ngay!$A$3:$A$100000,"<=7",Ngay!$Q$3:$Q$100000,$R3,Ngay!$R$3:$R$100000,$S3) | E3: =IF(C3>=D3,C3-D3,0) | F3: 1 | G3: =SUMIFS(Ngay!$B$3:$B$100000,Ngay!$A$3:$A$100000,">=8",Ngay!$A$3:$A$100000,"<=14",Ngay!$Q$3:$Q$100000,$R3,Ngay!$R$3:$R$100000,$S3) | H3: =IF(F3>=G3,F3-G3,0) | I3: 2 | J3: =SUMIFS(Ngay!$B$3:$B$100000,Ngay!$A$3:$A$100000,">=15",Ngay!$A$3:$A$100000,"<=21",Ngay!$Q$3:$Q$100000,$R3,Ngay!$R$3:$R$100000,$S3) | K3: =IF(I3>=J3,I3-J3,0) | L3: 2 | M3: =SUMIFS(Ngay!$B$3:$B$100000,Ngay!$A$3:$A$100000,">=22",Ngay!$A$3:$A$100000,"<=31",Ngay!$Q$3:$Q$100000,$R3,Ngay!$R$3:$R$100000,$S3) | N3: =IF(L3>=M3,L3-M3,0) | O3: 4 | P3: =D3+G3+J3+M3 | Q3: =IF(O3>=P3,O3-P3,0) | R3: 11 | S3: 2025
A4: TTVT Xuân Lộc | B4: Tiếp thị DV MyTV | C4: 1 | D4: =SUMIFS(Ngay!$C$3:$C$100000,Ngay!$A$3:$A$100000,">=1",Ngay!$A$3:$A$100000,"<=7",Ngay!$Q$3:$Q$100000,$R4,Ngay!$R$3:$R$100000,$S4) | E4: =IF(C4>=D4,C4-D4,0) | F4: 1 | G4: =SUMIFS(Ngay!$C$3:$C$100000,Ngay!$A$3:$A$100000,">=8",Ngay!$A$3:$A$100000,"<=14",Ngay!$Q$3:$Q$100000,$R4,Ngay!$R$3:$R$100000,$S4) | H4: =IF(F4>=G4,F4-G4,0) | I4: 2 | J4: =SUMIFS(Ngay!$C$3:$C$100000,Ngay!$A$3:$A$100000,">=15",Ngay!$A$3:$A$100000,"<=21",Ngay!$Q$3:$Q$100000,$R4,Ngay!$R$3:$R$100000,$S4) | K4: =IF(I4>=J4,I4-J4,0) | L4: 2 | M4: =SUMIFS(Ngay!$C$3:$C$100000,Ngay!$A$3:$A$100000,">=22",Ngay!$A$3:$A$100000,"<=31",Ngay!$Q$3:$Q$100000,$R4,Ngay!$R$3:$R$100000,$S4) | N4: =IF(L4>=M4,L4-M4,0) | O4: 5 | P4: =D4+G4+J4+M4 | Q4: =IF(O4>=P4,O4-P4,0) | R4: 11 | S4: 2025
A5: TTVT Xuân Lộc | B5: Tiếp thị DV Camera/Mesh | C5: 1 | D5: =SUMIFS(Ngay!$D$3:$D$100000,Ngay!$A$3:$A$100000,">=1",Ngay!$A$3:$A$100000,"<=7",Ngay!$Q$3:$Q$100000,$R5,Ngay!$R$3:$R$100000,$S5) | E5: =IF(C5>=D5,C5-D5,0) | F5: 1 | G5: =SUMIFS(Ngay!$D$3:$D$100000,Ngay!$A$3:$A$100000,">=8",Ngay!$A$3:$A$100000,"<=14",Ngay!$Q$3:$Q$100000,$R5,Ngay!$R$3:$R$100000,$S5) | H5: =IF(F5>=G5,F5-G5,0) | I5: 2 | J5: =SUMIFS(Ngay!$D$3:$D$100000,Ngay!$A$3:$A$100000,">=15",Ngay!$A$3:$A$100000,"<=21",Ngay!$Q$3:$Q$100000,$R5,Ngay!$R$3:$R$100000,$S5) | K5: =IF(I5>=J5,I5-J5,0) | L5: 2 | M5: =SUMIFS(Ngay!$D$3:$D$100000,Ngay!$A$3:$A$100000,">=22",Ngay!$A$3:$A$100000,"<=31",Ngay!$Q$3:$Q$100000,$R5,Ngay!$R$3:$R$100000,$S5) | N5: =IF(L5>=M5,L5-M5,0) | O5: 6 | P5: =D5+G5+J5+M5 | Q5: =IF(O5>=P5,O5-P5,0) | R5: 11 | S5: 2025
A6: TTVT Xuân Lộc | B6: Tạm ngưng Fiber | D6: =SUMIFS(Ngay!$E$3:$E$100000,Ngay!$A$3:$A$100000,">=1",Ngay!$A$3:$A$100000,"<=7",Ngay!$Q$3:$Q$100000,$R6,Ngay!$R$3:$R$100000,$S6) | E6: =IF(C6>=D6,C6-D6,0) | G6: =SUMIFS(Ngay!$E$3:$E$100000,Ngay!$A$3:$A$100000,">=8",Ngay!$A$3:$A$100000,"<=14",Ngay!$Q$3:$Q$100000,$R6,Ngay!$R$3:$R$100000,$S6) | H6: =IF(F6>=G6,F6-G6,0) | J6: =SUMIFS(Ngay!$E$3:$E$100000,Ngay!$A$3:$A$100000,">=15",Ngay!$A$3:$A$100000,"<=21",Ngay!$Q$3:$Q$100000,$R6,Ngay!$R$3:$R$100000,$S6) | K6: =IF(I6>=J6,I6-J6,0) | M6: =SUMIFS(Ngay!$E$3:$E$100000,Ngay!$A$3:$A$100000,">=22",Ngay!$A$3:$A$100000,"<=31",Ngay!$Q$3:$Q$100000,$R6,Ngay!$R$3:$R$100000,$S6) | N6: =IF(L6>=M6,L6-M6,0) | O6: 4 | P6: =D6+G6+J6+M6 | Q6: =IF(O6>=P6,O6-P6,0) | R6: 11 | S6: 2025
A7: TTVT Xuân Lộc | B7: Tạm ngưng Mytv | D7: =SUMIFS(Ngay!$F$3:$F$100000,Ngay!$A$3:$A$100000,">=1",Ngay!$A$3:$A$100000,"<=7",Ngay!$Q$3:$Q$100000,$R7,Ngay!$R$3:$R$100000,$S7) | E7: =IF(C7>=D7,C7-D7,0) | G7: =SUMIFS(Ngay!$F$3:$F$100000,Ngay!$A$3:$A$100000,">=8",Ngay!$A$3:$A$100000,"<=14",Ngay!$Q$3:$Q$100000,$R7,Ngay!$R$3:$R$100000,$S7) | H7: =IF(F7>=G7,F7-G7,0) | J7: =SUMIFS(Ngay!$F$3:$F$100000,Ngay!$A$3:$A$100000,">=15",Ngay!$A$3:$A$100000,"<=21",Ngay!$Q$3:$Q$100000,$R7,Ngay!$R$3:$R$100000,$S7) | K7: =IF(I7>=J7,I7-J7,0) | M7: =SUMIFS(Ngay!$F$3:$F$100000,Ngay!$A$3:$A$100000,">=22",Ngay!$A$3:$A$100000,"<=31",Ngay!$Q$3:$Q$100000,$R7,Ngay!$R$3:$R$100000,$S7) | N7: =IF(L7>=M7,L7-M7,0) | O7: 2 | P7: =D7+G7+J7+M7 | Q7: =IF(O7>=P7,O7-P7,0) | R7: 11 | S7: 2025
A8: TTVT Xuân Lộc | B8: Thay thế ONT 2 băng tần | C8: 10 | D8: =SUMIFS(Ngay!$G$3:$G$100000,Ngay!$A$3:$A$100000,">=1",Ngay!$A$3:$A$100000,"<=7",Ngay!$Q$3:$Q$100000,$R8,Ngay!$R$3:$R$100000,$S8) | E8: =IF(C8>=D8,C8-D8,0) | F8: 10 | G8: =SUMIFS(Ngay!$G$3:$G$100000,Ngay!$A$3:$A$100000,">=8",Ngay!$A$3:$A$100000,"<=14",Ngay!$Q$3:$Q$100000,$R8,Ngay!$R$3:$R$100000,$S8) | H8: =IF(F8>=G8,F8-G8,0) | I8: 10 | J8: =SUMIFS(Ngay!$G$3:$G$100000,Ngay!$A$3:$A$100000,">=15",Ngay!$A$3:$A$100000,"<=21",Ngay!$Q$3:$Q$100000,$R8,Ngay!$R$3:$R$100000,$S8) | K8: =IF(I8>=J8,I8-J8,0) | L8: 10 | M8: =SUMIFS(Ngay!$G$3:$G$100000,Ngay!$A$3:$A$100000,">=22",Ngay!$A$3:$A$100000,"<=31",Ngay!$Q$3:$Q$100000,$R8,Ngay!$R$3:$R$100000,$S8) | N8: =IF(L8>=M8,L8-M8,0) | O8: 40 | P8: =D8+G8+J8+M8 | Q8: =IF(O8>=P8,O8-P8,0) | R8: 11 | S8: 2025
A9: TTVT Xuân Lộc | B9: CSKH HVC chuyển XGSPON | C9: 10 | D9: =SUMIFS(Ngay!$H$3:$H$100000,Ngay!$A$3:$A$100000,">=1",Ngay!$A$3:$A$100000,"<=7",Ngay!$Q$3:$Q$100000,$R9,Ngay!$R$3:$R$100000,$S9) | E9: =IF(C9>=D9,C9-D9,0) | F9: 10 | G9: =SUMIFS(Ngay!$H$3:$H$100000,Ngay!$A$3:$A$100000,">=8",Ngay!$A$3:$A$100000,"<=14",Ngay!$Q$3:$Q$100000,$R9,Ngay!$R$3:$R$100000,$S9) | H9: =IF(F9>=G9,F9-G9,0) | I9: 10 | J9: =SUMIFS(Ngay!$H$3:$H$100000,Ngay!$A$3:$A$100000,">=15",Ngay!$A$3:$A$100000,"<=31",Ngay!$Q$3:$Q$100000,$R9,Ngay!$R$3:$R$100000,$S9) | K9: =IF(I9>=J9,I9-J9,0) | L9: 10 | M9: =SUMIFS(Ngay!$H$3:$H$100000,Ngay!$A$3:$A$100000,">=22",Ngay!$A$3:$A$100000,"<=31",Ngay!$Q$3:$Q$100000,$R9,Ngay!$R$3:$R$100000,$S9) | N9: =IF(L9>=M9,L9-M9,0) | O9: 20 | P9: =D9+G9+J9+M9 | Q9: =IF(O9>=P9,O9-P9,0) | R9: 11 | S9: 2025
A10: TTVT Xuân Lộc | B10: Phiếu GHTT tháng T | C10: 50 | D10: =SUMIFS(Ngay!$I$3:$I$100000,Ngay!$A$3:$A$100000,">=1",Ngay!$A$3:$A$100000,"<=7",Ngay!$Q$3:$Q$100000,$R10,Ngay!$R$3:$R$100000,$S10) | E10: =IF(C10>=D10,C10-D10,0) | F10: 50 | G10: =SUMIFS(Ngay!$I$3:$I$100000,Ngay!$A$3:$A$100000,">=8",Ngay!$A$3:$A$100000,"<=14",Ngay!$Q$3:$Q$100000,$R10,Ngay!$R$3:$R$100000,$S10) | H10: =IF(F10>=G10,F10-G10,0) | I10: 50 | J10: =SUMIFS(Ngay!$I$3:$I$100000,Ngay!$A$3:$A$100000,">=15",Ngay!$A$3:$A$100000,"<=21",Ngay!$Q$3:$Q$100000,$R10,Ngay!$R$3:$R$100000,$S10) | K10: =IF(I10>=J10,I10-J10,0) | L10: 50 | M10: =SUMIFS(Ngay!$I$3:$I$100000,Ngay!$A$3:$A$100000,">=22",Ngay!$A$3:$A$100000,"<=31",Ngay!$Q$3:$Q$100000,$R10,Ngay!$R$3:$R$100000,$S10) | N10: =IF(L10>=M10,L10-M10,0) | O10: 150 | P10: =D10+G10+J10+M10 | Q10: =IF(O10>=P10,O10-P10,0) | R10: 11 | S10: 2025
A11: TTVT Xuân Lộc | B11: Phiếu GHTT tháng T+1 | C11: 10 | D11: =SUMIFS(Ngay!$J$3:$J$100000,Ngay!$A$3:$A$100000,">=1",Ngay!$A$3:$A$100000,"<=7",Ngay!$Q$3:$Q$100000,$R11,Ngay!$R$3:$R$100000,$S11) | E11: =IF(C11>=D11,C11-D11,0) | F11: 10 | G11: =SUMIFS(Ngay!$J$3:$J$100000,Ngay!$A$3:$A$100000,">=8",Ngay!$A$3:$A$100000,"<=14",Ngay!$Q$3:$Q$100000,$R11,Ngay!$R$3:$R$100000,$S11) | H11: =IF(F11>=G11,F11-G11,0) | I11: 10 | J11: =SUMIFS(Ngay!$J$3:$J$100000,Ngay!$A$3:$A$100000,">=15",Ngay!$A$3:$A$100000,"<=21",Ngay!$Q$3:$Q$100000,$R11,Ngay!$R$3:$R$100000,$S11) | K11: =IF(I11>=J11,I11-J11,0) | L11: 10 | M11: =SUMIFS(Ngay!$J$3:$J$100000,Ngay!$A$3:$A$100000,">=22",Ngay!$A$3:$A$100000,"<=31",Ngay!$Q$3:$Q$100000,$R11,Ngay!$R$3:$R$100000,$S11) | N11: =IF(L11>=M11,L11-M11,0) | O11: 1 | P11: =D11+G11+J11+M11 | Q11: =IF(O11>=P11,O11-P11,0) | R11: 11 | S11: 2025
A12: TTVT Xuân Lộc | B12: Tiếp thị DV Fiber | C12: 1 | D12: =SUMIFS(Ngay!$B$3:$B$100000,Ngay!$A$3:$A$100000,">=1",Ngay!$A$3:$A$100000,"<=7",Ngay!$Q$3:$Q$100000,$R12,Ngay!$R$3:$R$100000,$S12) | E12: =IF(C12>=D12,C12-D12,0) | F12: 1 | G12: =SUMIFS(Ngay!$B$3:$B$100000,Ngay!$A$3:$A$100000,">=8",Ngay!$A$3:$A$100000,"<=14",Ngay!$Q$3:$Q$100000,$R12,Ngay!$R$3:$R$100000,$S12) | H12: =IF(F12>=G12,F12-G12,0) | I12: 2 | J12: =SUMIFS(Ngay!$B$3:$B$100000,Ngay!$A$3:$A$100000,">=15",Ngay!$A$3:$A$100000,"<=21",Ngay!$Q$3:$Q$100000,$R12,Ngay!$R$3:$R$100000,$S12) | K12: =IF(I12>=J12,I12-J12,0) | L12: 2 | M12: =SUMIFS(Ngay!$B$3:$B$100000,Ngay!$A$3:$A$100000,">=22",Ngay!$A$3:$A$100000,"<=31",Ngay!$Q$3:$Q$100000,$R12,Ngay!$R$3:$R$100000,$S12) | N12: =IF(L12>=M12,L12-M12,0) | O12: 4 | P12: =D12+G12+J12+M12 | Q12: =IF(O12>=P12,O12-P12,0) | R12: 12 | S12: 2025
A13: TTVT Xuân Lộc | B13: Tiếp thị DV MyTV | C13: 1 | D13: =SUMIFS(Ngay!$C$3:$C$100000,Ngay!$A$3:$A$100000,">=1",Ngay!$A$3:$A$100000,"<=7",Ngay!$Q$3:$Q$100000,$R13,Ngay!$R$3:$R$100000,$S13) | E13: =IF(C13>=D13,C13-D13,0) | F13: 1 | G13: =SUMIFS(Ngay!$C$3:$C$100000,Ngay!$A$3:$A$100000,">=8",Ngay!$A$3:$A$100000,"<=14",Ngay!$Q$3:$Q$100000,$R13,Ngay!$R$3:$R$100000,$S13) | H13: =IF(F13>=G13,F13-G13,0) | I13: 2 | J13: =SUMIFS(Ngay!$C$3:$C$100000,Ngay!$A$3:$A$100000,">=15",Ngay!$A$3:$A$100000,"<=21",Ngay!$Q$3:$Q$100000,$R13,Ngay!$R$3:$R$100000,$S13) | K13: =IF(I13>=J13,I13-J13,0) | L13: 2 | M13: =SUMIFS(Ngay!$C$3:$C$100000,Ngay!$A$3:$A$100000,">=22",Ngay!$A$3:$A$100000,"<=31",Ngay!$Q$3:$Q$100000,$R13,Ngay!$R$3:$R$100000,$S13) | N13: =IF(L13>=M13,L13-M13,0) | O13: 5 | P13: =D13+G13+J13+M13 | Q13: =IF(O13>=P13,O13-P13,0) | R13: 12 | S13: 2025
A14: TTVT Xuân Lộc | B14: Tiếp thị DV Camera/Mesh | C14: 1 | D14: =SUMIFS(Ngay!$D$3:$D$100000,Ngay!$A$3:$A$100000,">=1",Ngay!$A$3:$A$100000,"<=7",Ngay!$Q$3:$Q$100000,$R14,Ngay!$R$3:$R$100000,$S14) | E14: =IF(C14>=D14,C14-D14,0) | F14: 1 | G14: =SUMIFS(Ngay!$D$3:$D$100000,Ngay!$A$3:$A$100000,">=8",Ngay!$A$3:$A$100000,"<=14",Ngay!$Q$3:$Q$100000,$R14,Ngay!$R$3:$R$100000,$S14) | H14: =IF(F14>=G14,F14-G14,0) | I14: 2 | J14: =SUMIFS(Ngay!$D$3:$D$100000,Ngay!$A$3:$A$100000,">=15",Ngay!$A$3:$A$100000,"<=21",Ngay!$Q$3:$Q$100000,$R14,Ngay!$R$3:$R$100000,$S14) | K14: =IF(I14>=J14,I14-J14,0) | L14: 2 | M14: =SUMIFS(Ngay!$D$3:$D$100000,Ngay!$A$3:$A$100000,">=22",Ngay!$A$3:$A$100000,"<=31",Ngay!$Q$3:$Q$100000,$R14,Ngay!$R$3:$R$100000,$S14) | N14: =IF(L14>=M14,L14-M14,0) | O14: 6 | P14: =D14+G14+J14+M14 | Q14: =IF(O14>=P14,O14-P14,0) | R14: 12 | S14: 2025
A15: TTVT Xuân Lộc | B15: Tạm ngưng Fiber | D15: =SUMIFS(Ngay!$E$3:$E$100000,Ngay!$A$3:$A$100000,">=1",Ngay!$A$3:$A$100000,"<=7",Ngay!$Q$3:$Q$100000,$R15,Ngay!$R$3:$R$100000,$S15) | E15: =IF(C15>=D15,C15-D15,0) | G15: =SUMIFS(Ngay!$E$3:$E$100000,Ngay!$A$3:$A$100000,">=8",Ngay!$A$3:$A$100000,"<=14",Ngay!$Q$3:$Q$100000,$R15,Ngay!$R$3:$R$100000,$S15) | H15: =IF(F15>=G15,F15-G15,0) | J15: =SUMIFS(Ngay!$E$3:$E$100000,Ngay!$A$3:$A$100000,">=15",Ngay!$A$3:$A$100000,"<=21",Ngay!$Q$3:$Q$100000,$R15,Ngay!$R$3:$R$100000,$S15) | K15: =IF(I15>=J15,I15-J15,0) | M15: =SUMIFS(Ngay!$E$3:$E$100000,Ngay!$A$3:$A$100000,">=22",Ngay!$A$3:$A$100000,"<=31",Ngay!$Q$3:$Q$100000,$R15,Ngay!$R$3:$R$100000,$S15) | N15: =IF(L15>=M15,L15-M15,0) | O15: 4 | P15: =D15+G15+J15+M15 | Q15: =IF(O15>=P15,O15-P15,0) | R15: 12 | S15: 2025
A16: TTVT Xuân Lộc | B16: Tạm ngưng Mytv | D16: =SUMIFS(Ngay!$F$3:$F$100000,Ngay!$A$3:$A$100000,">=1",Ngay!$A$3:$A$100000,"<=7",Ngay!$Q$3:$Q$100000,$R16,Ngay!$R$3:$R$100000,$S16) | E16: =IF(C16>=D16,C16-D16,0) | G16: =SUMIFS(Ngay!$F$3:$F$100000,Ngay!$A$3:$A$100000,">=8",Ngay!$A$3:$A$100000,"<=14",Ngay!$Q$3:$Q$100000,$R16,Ngay!$R$3:$R$100000,$S16) | H16: =IF(F16>=G16,F16-G16,0) | J16: =SUMIFS(Ngay!$F$3:$F$100000,Ngay!$A$3:$A$100000,">=15",Ngay!$A$3:$A$100000,"<=21",Ngay!$Q$3:$Q$100000,$R16,Ngay!$R$3:$R$100000,$S16) | K16: =IF(I16>=J16,I16-J16,0) | M16: =SUMIFS(Ngay!$F$3:$F$100000,Ngay!$A$3:$A$100000,">=22",Ngay!$A$3:$A$100000,"<=31",Ngay!$Q$3:$Q$100000,$R16,Ngay!$R$3:$R$100000,$S16) | N16: =IF(L16>=M16,L16-M16,0) | O16: 2 | P16: =D16+G16+J16+M16 | Q16: =IF(O16>=P16,O16-P16,0) | R16: 12 | S16: 2025
A17: TTVT Xuân Lộc | B17: Thay thế ONT 2 băng tần | C17: 10 | D17: =SUMIFS(Ngay!$G$3:$G$100000,Ngay!$A$3:$A$100000,">=1",Ngay!$A$3:$A$100000,"<=7",Ngay!$Q$3:$Q$100000,$R17,Ngay!$R$3:$R$100000,$S17) | E17: =IF(C17>=D17,C17-D17,0) | F17: 10 | G17: =SUMIFS(Ngay!$G$3:$G$100000,Ngay!$A$3:$A$100000,">=8",Ngay!$A$3:$A$100000,"<=14",Ngay!$Q$3:$Q$100000,$R17,Ngay!$R$3:$R$100000,$S17) | H17: =IF(F17>=G17,F17-G17,0) | I17: 10 | J17: =SUMIFS(Ngay!$G$3:$G$100000,Ngay!$A$3:$A$100000,">=15",Ngay!$A$3:$A$100000,"<=21",Ngay!$Q$3:$Q$100000,$R17,Ngay!$R$3:$R$100000,$S17) | K17: =IF(I17>=J17,I17-J17,0) | L17: 10 | M17: =SUMIFS(Ngay!$G$3:$G$100000,Ngay!$A$3:$A$100000,">=22",Ngay!$A$3:$A$100000,"<=31",Ngay!$Q$3:$Q$100000,$R17,Ngay!$R$3:$R$100000,$S17) | N17: =IF(L17>=M17,L17-M17,0) | O17: 40 | P17: =D17+G17+J17+M17 | Q17: =IF(O17>=P17,O17-P17,0) | R17: 12 | S17: 2025
A18: TTVT Xuân Lộc | B18: CSKH HVC chuyển XGSPON | C18: 10 | D18: =SUMIFS(Ngay!$H$3:$H$100000,Ngay!$A$3:$A$100000,">=1",Ngay!$A$3:$A$100000,"<=7",Ngay!$Q$3:$Q$100000,$R18,Ngay!$R$3:$R$100000,$S18) | E18: =IF(C18>=D18,C18-D18,0) | F18: 10 | G18: =SUMIFS(Ngay!$H$3:$H$100000,Ngay!$A$3:$A$100000,">=8",Ngay!$A$3:$A$100000,"<=14",Ngay!$Q$3:$Q$100000,$R18,Ngay!$R$3:$R$100000,$S18) | H18: =IF(F18>=G18,F18-G18,0) | I18: 10 | J18: =SUMIFS(Ngay!$H$3:$H$100000,Ngay!$A$3:$A$100000,">=15",Ngay!$A$3:$A$100000,"<=15",Ngay!$Q$3:$Q$100000,$R18,Ngay!$R$3:$R$100000,$S18) | K18: =IF(I18>=J18,I18-J18,0) | L18: 10 | M18: =SUMIFS(Ngay!$H$3:$H$100000,Ngay!$A$3:$A$100000,">=22",Ngay!$A$3:$A$100000,"<=31",Ngay!$Q$3:$Q$100000,$R18,Ngay!$R$3:$R$100000,$S18) | N18: =IF(L18>=M18,L18-M18,0) | O18: 20 | P18: =D18+G18+J18+M18 | Q18: =IF(O18>=P18,O18-P18,0) | R18: 12 | S18: 2025
A19: TTVT Xuân Lộc | B19: Phiếu GHTT tháng T | C19: 50 | D19: =SUMIFS(Ngay!$I$3:$I$100000,Ngay!$A$3:$A$100000,">=1",Ngay!$A$3:$A$100000,"<=7",Ngay!$Q$3:$Q$100000,$R19,Ngay!$R$3:$R$100000,$S19) | E19: =IF(C19>=D19,C19-D19,0) | F19: 50 | G19: =SUMIFS(Ngay!$I$3:$I$100000,Ngay!$A$3:$A$100000,">=8",Ngay!$A$3:$A$100000,"<=14",Ngay!$Q$3:$Q$100000,$R19,Ngay!$R$3:$R$100000,$S19) | H19: =IF(F19>=G19,F19-G19,0) | I19: 50 | J19: =SUMIFS(Ngay!$I$3:$I$100000,Ngay!$A$3:$A$100000,">=15",Ngay!$A$3:$A$100000,"<=21",Ngay!$Q$3:$Q$100000,$R19,Ngay!$R$3:$R$100000,$S19) | K19: =IF(I19>=J19,I19-J19,0) | L19: 50 | M19: =SUMIFS(Ngay!$I$3:$I$100000,Ngay!$A$3:$A$100000,">=22",Ngay!$A$3:$A$100000,"<=31",Ngay!$Q$3:$Q$100000,$R19,Ngay!$R$3:$R$100000,$S19) | N19: =IF(L19>=M19,L19-M19,0) | O19: 150 | P19: =D19+G19+J19+M19 | Q19: =IF(O19>=P19,O19-P19,0) | R19: 12 | S19: 2025
A20: TTVT Xuân Lộc | B20: Phiếu GHTT tháng T+1 | C20: 10 | D20: =SUMIFS(Ngay!$J$3:$J$100000,Ngay!$A$3:$A$100000,">=1",Ngay!$A$3:$A$100000,"<=7",Ngay!$Q$3:$Q$100000,$R20,Ngay!$R$3:$R$100000,$S20) | E20: =IF(C20>=D20,C20-D20,0) | F20: 10 | G20: =SUMIFS(Ngay!$J$3:$J$100000,Ngay!$A$3:$A$100000,">=8",Ngay!$A$3:$A$100000,"<=14",Ngay!$Q$3:$Q$100000,$R20,Ngay!$R$3:$R$100000,$S20) | H20: =IF(F20>=G20,F20-G20,0) | I20: 10 | J20: =SUMIFS(Ngay!$J$3:$J$100000,Ngay!$A$3:$A$100000,">=15",Ngay!$A$3:$A$100000,"<=21",Ngay!$Q$3:$Q$100000,$R20,Ngay!$R$3:$R$100000,$S20) | K20: =IF(I20>=J20,I20-J20,0) | L20: 10 | M20: =SUMIFS(Ngay!$J$3:$J$100000,Ngay!$A$3:$A$100000,">=22",Ngay!$A$3:$A$100000,"<=31",Ngay!$Q$3:$Q$100000,$R20,Ngay!$R$3:$R$100000,$S20) | N20: =IF(L20>=M20,L20-M20,0) | O20: 1 | P20: =D20+G20+J20+M20 | Q20: =IF(O20>=P20,O20-P20,0) | R20: 12 | S20: 2025
A21: TTVT Xuân Lộc | B21: Tiếp thị DV Fiber | C21: 1 | D21: =SUMIFS(Ngay!$B$3:$B$100000,Ngay!$A$3:$A$100000,">=1",Ngay!$A$3:$A$100000,"<=7",Ngay!$Q$3:$Q$100000,$R21,Ngay!$R$3:$R$100000,$S21) | E21: =IF(C21>=D21,C21-D21,0) | F21: 1 | G21: =SUMIFS(Ngay!$B$3:$B$100000,Ngay!$A$3:$A$100000,">=8",Ngay!$A$3:$A$100000,"<=14",Ngay!$Q$3:$Q$100000,$R21,Ngay!$R$3:$R$100000,$S21) | H21: =IF(F21>=G21,F21-G21,0) | I21: 2 | J21: =SUMIFS(Ngay!$B$3:$B$100000,Ngay!$A$3:$A$100000,">=15",Ngay!$A$3:$A$100000,"<=21",Ngay!$Q$3:$Q$100000,$R21,Ngay!$R$3:$R$100000,$S21) | K21: =IF(I21>=J21,I21-J21,0) | L21: 2 | M21: =SUMIFS(Ngay!$B$3:$B$100000,Ngay!$A$3:$A$100000,">=22",Ngay!$A$3:$A$100000,"<=31",Ngay!$Q$3:$Q$100000,$R21,Ngay!$R$3:$R$100000,$S21) | N21: =IF(L21>=M21,L21-M21,0) | O21: 4 | P21: =D21+G21+J21+M21 | Q21: =IF(O21>=P21,O21-P21,0) | R21: 1 | S21: 2026
A22: TTVT Xuân Lộc | B22: Tiếp thị DV MyTV | C22: 1 | D22: =SUMIFS(Ngay!$C$3:$C$100000,Ngay!$A$3:$A$100000,">=1",Ngay!$A$3:$A$100000,"<=7",Ngay!$Q$3:$Q$100000,$R22,Ngay!$R$3:$R$100000,$S22) | E22: =IF(C22>=D22,C22-D22,0) | F22: 1 | G22: =SUMIFS(Ngay!$C$3:$C$100000,Ngay!$A$3:$A$100000,">=8",Ngay!$A$3:$A$100000,"<=14",Ngay!$Q$3:$Q$100000,$R22,Ngay!$R$3:$R$100000,$S22) | H22: =IF(F22>=G22,F22-G22,0) | I22: 2 | J22: =SUMIFS(Ngay!$C$3:$C$100000,Ngay!$A$3:$A$100000,">=15",Ngay!$A$3:$A$100000,"<=21",Ngay!$Q$3:$Q$100000,$R22,Ngay!$R$3:$R$100000,$S22) | K22: =IF(I22>=J22,I22-J22,0) | L22: 2 | M22: =SUMIFS(Ngay!$C$3:$C$100000,Ngay!$A$3:$A$100000,">=22",Ngay!$A$3:$A$100000,"<=31",Ngay!$Q$3:$Q$100000,$R22,Ngay!$R$3:$R$100000,$S22) | N22: =IF(L22>=M22,L22-M22,0) | O22: 5 | P22: =D22+G22+J22+M22 | Q22: =IF(O22>=P22,O22-P22,0) | R22: 1 | S22: 2026
A23: TTVT Xuân Lộc | B23: Tiếp thị DV Camera/Mesh | C23: 1 | D23: =SUMIFS(Ngay!$D$3:$D$100000,Ngay!$A$3:$A$100000,">=1",Ngay!$A$3:$A$100000,"<=7",Ngay!$Q$3:$Q$100000,$R23,Ngay!$R$3:$R$100000,$S23) | E23: =IF(C23>=D23,C23-D23,0) | F23: 1 | G23: =SUMIFS(Ngay!$D$3:$D$100000,Ngay!$A$3:$A$100000,">=8",Ngay!$A$3:$A$100000,"<=14",Ngay!$Q$3:$Q$100000,$R23,Ngay!$R$3:$R$100000,$S23) | H23: =IF(F23>=G23,F23-G23,0) | I23: 2 | J23: =SUMIFS(Ngay!$D$3:$D$100000,Ngay!$A$3:$A$100000,">=15",Ngay!$A$3:$A$100000,"<=21",Ngay!$Q$3:$Q$100000,$R23,Ngay!$R$3:$R$100000,$S23) | K23: =IF(I23>=J23,I23-J23,0) | L23: 2 | M23: =SUMIFS(Ngay!$D$3:$D$100000,Ngay!$A$3:$A$100000,">=22",Ngay!$A$3:$A$100000,"<=31",Ngay!$Q$3:$Q$100000,$R23,Ngay!$R$3:$R$100000,$S23) | N23: =IF(L23>=M23,L23-M23,0) | O23: 6 | P23: =D23+G23+J23+M23 | Q23: =IF(O23>=P23,O23-P23,0) | R23: 1 | S23: 2026
A24: TTVT Xuân Lộc | B24: Tạm ngưng Fiber | D24: =SUMIFS(Ngay!$E$3:$E$100000,Ngay!$A$3:$A$100000,">=1",Ngay!$A$3:$A$100000,"<=7",Ngay!$Q$3:$Q$100000,$R24,Ngay!$R$3:$R$100000,$S24) | E24: =IF(C24>=D24,C24-D24,0) | G24: =SUMIFS(Ngay!$E$3:$E$100000,Ngay!$A$3:$A$100000,">=8",Ngay!$A$3:$A$100000,"<=14",Ngay!$Q$3:$Q$100000,$R24,Ngay!$R$3:$R$100000,$S24) | H24: =IF(F24>=G24,F24-G24,0) | J24: =SUMIFS(Ngay!$E$3:$E$100000,Ngay!$A$3:$A$100000,">=15",Ngay!$A$3:$A$100000,"<=21",Ngay!$Q$3:$Q$100000,$R24,Ngay!$R$3:$R$100000,$S24) | K24: =IF(I24>=J24,I24-J24,0) | M24: =SUMIFS(Ngay!$E$3:$E$100000,Ngay!$A$3:$A$100000,">=22",Ngay!$A$3:$A$100000,"<=31",Ngay!$Q$3:$Q$100000,$R24,Ngay!$R$3:$R$100000,$S24) | N24: =IF(L24>=M24,L24-M24,0) | O24: 4 | P24: =D24+G24+J24+M24 | Q24: =IF(O24>=P24,O24-P24,0) | R24: 1 | S24: 2026
A25: TTVT Xuân Lộc | B25: Tạm ngưng Mytv | D25: =SUMIFS(Ngay!$F$3:$F$100000,Ngay!$A$3:$A$100000,">=1",Ngay!$A$3:$A$100000,"<=7",Ngay!$Q$3:$Q$100000,$R25,Ngay!$R$3:$R$100000,$S25) | E25: =IF(C25>=D25,C25-D25,0) | G25: =SUMIFS(Ngay!$F$3:$F$100000,Ngay!$A$3:$A$100000,">=8",Ngay!$A$3:$A$100000,"<=14",Ngay!$Q$3:$Q$100000,$R25,Ngay!$R$3:$R$100000,$S25) | H25: =IF(F25>=G25,F25-G25,0) | J25: =SUMIFS(Ngay!$F$3:$F$100000,Ngay!$A$3:$A$100000,">=15",Ngay!$A$3:$A$100000,"<=21",Ngay!$Q$3:$Q$100000,$R25,Ngay!$R$3:$R$100000,$S25) | K25: =IF(I25>=J25,I25-J25,0) | M25: =SUMIFS(Ngay!$F$3:$F$100000,Ngay!$A$3:$A$100000,">=22",Ngay!$A$3:$A$100000,"<=31",Ngay!$Q$3:$Q$100000,$R25,Ngay!$R$3:$R$100000,$S25) | N25: =IF(L25>=M25,L25-M25,0) | O25: 2 | P25: =D25+G25+J25+M25 | Q25: =IF(O25>=P25,O25-P25,0) | R25: 1 | S25: 2026
A26: TTVT Xuân Lộc | B26: Thay thế ONT 2 băng tần | C26: 10 | D26: =SUMIFS(Ngay!$G$3:$G$100000,Ngay!$A$3:$A$100000,">=1",Ngay!$A$3:$A$100000,"<=7",Ngay!$Q$3:$Q$100000,$R26,Ngay!$R$3:$R$100000,$S26) | E26: =IF(C26>=D26,C26-D26,0) | F26: 10 | G26: =SUMIFS(Ngay!$G$3:$G$100000,Ngay!$A$3:$A$100000,">=8",Ngay!$A$3:$A$100000,"<=14",Ngay!$Q$3:$Q$100000,$R26,Ngay!$R$3:$R$100000,$S26) | H26: =IF(F26>=G26,F26-G26,0) | I26: 10 | J26: =SUMIFS(Ngay!$G$3:$G$100000,Ngay!$A$3:$A$100000,">=15",Ngay!$A$3:$A$100000,"<=21",Ngay!$Q$3:$Q$100000,$R26,Ngay!$R$3:$R$100000,$S26) | K26: =IF(I26>=J26,I26-J26,0) | L26: 10 | M26: =SUMIFS(Ngay!$G$3:$G$100000,Ngay!$A$3:$A$100000,">=22",Ngay!$A$3:$A$100000,"<=31",Ngay!$Q$3:$Q$100000,$R26,Ngay!$R$3:$R$100000,$S26) | N26: =IF(L26>=M26,L26-M26,0) | O26: 40 | P26: =D26+G26+J26+M26 | Q26: =IF(O26>=P26,O26-P26,0) | R26: 1 | S26: 2026
A27: TTVT Xuân Lộc | B27: CSKH HVC chuyển XGSPON | C27: 10 | D27: =SUMIFS(Ngay!$H$3:$H$100000,Ngay!$A$3:$A$100000,">=1",Ngay!$A$3:$A$100000,"<=7",Ngay!$Q$3:$Q$100000,$R27,Ngay!$R$3:$R$100000,$S27) | E27: =IF(C27>=D27,C27-D27,0) | F27: 10 | G27: =SUMIFS(Ngay!$H$3:$H$100000,Ngay!$A$3:$A$100000,">=8",Ngay!$A$3:$A$100000,"<=14",Ngay!$Q$3:$Q$100000,$R27,Ngay!$R$3:$R$100000,$S27) | H27: =IF(F27>=G27,F27-G27,0) | I27: 10 | J27: =SUMIFS(Ngay!$H$3:$H$100000,Ngay!$A$3:$A$100000,">=15",Ngay!$A$3:$A$100000,"<=15",Ngay!$Q$3:$Q$100000,$R27,Ngay!$R$3:$R$100000,$S27) | K27: =IF(I27>=J27,I27-J27,0) | L27: 10 | M27: =SUMIFS(Ngay!$H$3:$H$100000,Ngay!$A$3:$A$100000,">=22",Ngay!$A$3:$A$100000,"<=31",Ngay!$Q$3:$Q$100000,$R27,Ngay!$R$3:$R$100000,$S27) | N27: =IF(L27>=M27,L27-M27,0) | O27: 20 | P27: =D27+G27+J27+M27 | Q27: =IF(O27>=P27,O27-P27,0) | R27: 1 | S27: 2026
A28: TTVT Xuân Lộc | B28: Phiếu GHTT tháng T | C28: 50 | D28: =SUMIFS(Ngay!$I$3:$I$100000,Ngay!$A$3:$A$100000,">=1",Ngay!$A$3:$A$100000,"<=7",Ngay!$Q$3:$Q$100000,$R28,Ngay!$R$3:$R$100000,$S28) | E28: =IF(C28>=D28,C28-D28,0) | F28: 50 | G28: =SUMIFS(Ngay!$I$3:$I$100000,Ngay!$A$3:$A$100000,">=8",Ngay!$A$3:$A$100000,"<=14",Ngay!$Q$3:$Q$100000,$R28,Ngay!$R$3:$R$100000,$S28) | H28: =IF(F28>=G28,F28-G28,0) | I28: 50 | J28: =SUMIFS(Ngay!$I$3:$I$100000,Ngay!$A$3:$A$100000,">=15",Ngay!$A$3:$A$100000,"<=21",Ngay!$Q$3:$Q$100000,$R28,Ngay!$R$3:$R$100000,$S28) | K28: =IF(I28>=J28,I28-J28,0) | L28: 50 | M28: =SUMIFS(Ngay!$I$3:$I$100000,Ngay!$A$3:$A$100000,">=22",Ngay!$A$3:$A$100000,"<=31",Ngay!$Q$3:$Q$100000,$R28,Ngay!$R$3:$R$100000,$S28) | N28: =IF(L28>=M28,L28-M28,0) | O28: 150 | P28: =D28+G28+J28+M28 | Q28: =IF(O28>=P28,O28-P28,0) | R28: 1 | S28: 2026
A29: TTVT Xuân Lộc | B29: Phiếu GHTT tháng T+1 | C29: 10 | D29: =SUMIFS(Ngay!$J$3:$J$100000,Ngay!$A$3:$A$100000,">=1",Ngay!$A$3:$A$100000,"<=7",Ngay!$Q$3:$Q$100000,$R29,Ngay!$R$3:$R$100000,$S29) | E29: =IF(C29>=D29,C29-D29,0) | F29: 10 | G29: =SUMIFS(Ngay!$J$3:$J$100000,Ngay!$A$3:$A$100000,">=8",Ngay!$A$3:$A$100000,"<=14",Ngay!$Q$3:$Q$100000,$R29,Ngay!$R$3:$R$100000,$S29) | H29: =IF(F29>=G29,F29-G29,0) | I29: 10 | J29: =SUMIFS(Ngay!$J$3:$J$100000,Ngay!$A$3:$A$100000,">=15",Ngay!$A$3:$A$100000,"<=21",Ngay!$Q$3:$Q$100000,$R29,Ngay!$R$3:$R$100000,$S29) | K29: =IF(I29>=J29,I29-J29,0) | L29: 10 | M29: =SUMIFS(Ngay!$J$3:$J$100000,Ngay!$A$3:$A$100000,">=22",Ngay!$A$3:$A$100000,"<=31",Ngay!$Q$3:$Q$100000,$R29,Ngay!$R$3:$R$100000,$S29) | N29: =IF(L29>=M29,L29-M29,0) | O29: 1 | P29: =D29+G29+J29+M29 | Q29: =IF(O29>=P29,O29-P29,0) | R29: 1 | S29: 2026

Sheet Tuan_CaNhan
C1: Tuần 1 | F1: Tuần 2 | I1: Tuần 3 | L1: Tuần 4 | O1: Tháng
A2: Nhân Viên | B2: Mục tiêu | C2: KH giao | D2: Thực hiện | E2: Còn lại | F2: KH giao | G2: Thực hiện | H2: Còn lại | I2: KH giao | J2: Thực hiện | K2: Còn lại | L2: KH giao | M2: Thực hiện | N2: Còn lại | O2: KH giao | P2: Thực hiện | Q2: Còn lại | R2: Thang
A3: Trần Trung Giang | B3: Tiếp thị DV Fiber | C3: 2 | D3: =SUMIFS(DuLieu!$D$3:$D$11921,DuLieu!$B$3:$B$101921,$A3,DuLieu!$T$3:$T$101921,">=1", DuLieu!$T$3:$T$101921,"<=7",DuLieu!$U$3:$U$101921,$R3) | E3: =IF(C3>=D3,C3-D3,0) | F3: 2 | G3: =SUMIFS(DuLieu!$D$3:$D$11921,DuLieu!$B$3:$B$101921,$A3,DuLieu!$T$3:$T$101921,">=8", DuLieu!$T$3:$T$101921,"<=14",DuLieu!$U$3:$U$101921,$R3) | H3: =IF(F3>=G3,F3-G3,0) | I3: 2 | J3: =SUMIFS(DuLieu!$D$3:$D$11921,DuLieu!$B$3:$B$101921,$A3,DuLieu!$T$3:$T$101921,">=15", DuLieu!$T$3:$T$101921,"<=21",DuLieu!$U$3:$U$101921,$R3) | K3: =IF(I3>=J3,I3-J3,0) | L3: 1 | M3: =SUMIFS(DuLieu!$D$3:$D$101921,DuLieu!$B$3:$B$101921,$A3,DuLieu!$T$3:$T$101921,">=1", DuLieu!$T$3:$T$101921,"<=7",DuLieu!$U$3:$U$101921,$R3) | N3: =IF(L3>=M3,L3-M3,0) | O3: 4 | P3: =$D3+$G3+$J3+$M3 | Q3: =IF(O3>=P3,O3-P3,0) | R3: 11
A4: Trần Trung Giang | B4: Tiếp thị DV MyTV | C4: 2 | D4: =SUMIFS(DuLieu!$E$3:$E$11921,DuLieu!$B$3:$B$101921,$A4,DuLieu!$T$3:$T$101921,">=1", DuLieu!$T$3:$T$101921,"<=7",DuLieu!$U$3:$U$101921,$R4) | E4: =IF(C4>=D4,C4-D4,0) | F4: 2 | G4: =SUMIFS(DuLieu!$E$3:$E$11921,DuLieu!$B$3:$B$101921,$A4,DuLieu!$T$3:$T$101921,">=8", DuLieu!$T$3:$T$101921,"<=14",DuLieu!$U$3:$U$101921,$R4) | H4: =IF(F4>=G4,F4-G4,0) | I4: 2 | J4: =SUMIFS(DuLieu!$E$3:$E$11921,DuLieu!$B$3:$B$101921,$A4,DuLieu!$T$3:$T$101921,">=15", DuLieu!$T$3:$T$101921,"<=21",DuLieu!$U$3:$U$101921,$R4) | K4: =IF(I4>=J4,I4-J4,0) | L4: 1 | M4: =SUMIFS(DuLieu!$D$3:$D$101921,DuLieu!$B$3:$B$101921,$A4,DuLieu!$T$3:$T$101921,">=1", DuLieu!$T$3:$T$101921,"<=7",DuLieu!$U$3:$U$101921,$R4) | N4: =IF(L4>=M4,L4-M4,0) | O4: 5 | P4: =$D4+$G4+$J4+$M4 | Q4: =IF(O4>=P4,O4-P4,0) | R4: 11
A5: Trần Trung Giang | B5: Tiếp thị DV Camera/Mesh | C5: 1 | D5: =SUMIFS(DuLieu!$F$3:$F$11921,DuLieu!$B$3:$B$101921,$A5,DuLieu!$T$3:$T$101921,">=1", DuLieu!$T$3:$T$101921,"<=7",DuLieu!$U$3:$U$101921,$R5) | E5: =IF(C5>=D5,C5-D5,0) | F5: 1 | G5: =SUMIFS(DuLieu!$F$3:$F$11921,DuLieu!$B$3:$B$101921,$A5,DuLieu!$T$3:$T$101921,">=8", DuLieu!$T$3:$T$101921,"<=14",DuLieu!$U$3:$U$101921,$R5) | H5: =IF(F5>=G5,F5-G5,0) | I5: 0 | J5: =SUMIFS(DuLieu!$F$3:$F$11921,DuLieu!$B$3:$B$101921,$A5,DuLieu!$T$3:$T$101921,">=15", DuLieu!$T$3:$T$101921,"<=21",DuLieu!$U$3:$U$101921,$R5) | K5: =IF(I5>=J5,I5-J5,0) | L5: 0 | M5: =SUMIFS(DuLieu!$D$3:$D$101921,DuLieu!$B$3:$B$101921,$A5,DuLieu!$T$3:$T$101921,">=1", DuLieu!$T$3:$T$101921,"<=7",DuLieu!$U$3:$U$101921,$R5) | N5: =IF(L5>=M5,L5-M5,0) | O5: 6 | P5: =$D5+$G5+$J5+$M5 | Q5: =IF(O5>=P5,O5-P5,0) | R5: 11
A6: Trần Trung Giang | B6: Tạm ngưng Fiber | C6: 1 | D6: =SUMIFS(DuLieu!$G$3:$G$11921,DuLieu!$B$3:$B$101921,$A6,DuLieu!$T$3:$T$101921,">=1", DuLieu!$T$3:$T$101921,"<=7",DuLieu!$U$3:$U$101921,$R6) | E6: =IF(C6>=D6,C6-D6,0) | F6: 1 | G6: =SUMIFS(DuLieu!$G$3:$G$11921,DuLieu!$B$3:$B$101921,D6,DuLieu!$T$3:$T$101921,">=8", DuLieu!$T$3:$T$101921,"<=14",DuLieu!$U$3:$U$101921,$R6) | H6: =IF(F6>=G6,F6-G6,0) | I6: 1 | J6: =SUMIFS(DuLieu!$G$3:$G$11921,DuLieu!$B$3:$B$101921,$A6,DuLieu!$T$3:$T$101921,">=15", DuLieu!$T$3:$T$101921,"<=21",DuLieu!$U$3:$U$101921,$R6) | K6: =IF(I6>=J6,I6-J6,0) | L6: 1 | M6: =SUMIFS(DuLieu!$D$3:$D$101921,DuLieu!$B$3:$B$101921,$A6,DuLieu!$T$3:$T$101921,">=1", DuLieu!$T$3:$T$101921,"<=7",DuLieu!$U$3:$U$101921,$R6) | N6: =IF(L6>=M6,L6-M6,0) | O6: 4 | P6: =$D6+$G6+$J6+$M6 | Q6: =IF(O6>=P6,O6-P6,0) | R6: 11
A7: Trần Trung Giang | B7: Tạm ngưng Mytv | C7: 2 | D7: =SUMIFS(DuLieu!$H$3:$H$11921,DuLieu!$B$3:$B$101921,$A7,DuLieu!$T$3:$T$101921,">=1", DuLieu!$T$3:$T$101921,"<=7",DuLieu!$U$3:$U$101921,$R7) | E7: =IF(C7>=D7,C7-D7,0) | F7: 1 | G7: =SUMIFS(DuLieu!$H$3:$H$11921,DuLieu!$B$3:$B$101921,$A7,DuLieu!$T$3:$T$101921,">=8", DuLieu!$T$3:$T$101921,"<=14",DuLieu!$U$3:$U$101921,$R7) | H7: =IF(F7>=G7,F7-G7,0) | I7: 1 | J7: =SUMIFS(DuLieu!$H$3:$H$11921,DuLieu!$B$3:$B$101921,$A7,DuLieu!$T$3:$T$101921,">=15", DuLieu!$T$3:$T$101921,"<=21",DuLieu!$U$3:$U$101921,$R7) | K7: =IF(I7>=J7,I7-J7,0) | L7: 1 | M7: =SUMIFS(DuLieu!$D$3:$D$101921,DuLieu!$B$3:$B$101921,$A7,DuLieu!$T$3:$T$101921,">=1", DuLieu!$T$3:$T$101921,"<=7",DuLieu!$U$3:$U$101921,$R7) | N7: =IF(L7>=M7,L7-M7,0) | O7: 2 | P7: =$D7+$G7+$J7+$M7 | Q7: =IF(O7>=P7,O7-P7,0) | R7: 11
A8: Trần Trung Giang | B8: Thay thế ONT 2 băng tần | C8: 6 | D8: =SUMIFS(DuLieu!$I$3:$I$11921,DuLieu!$B$3:$B$101921,$A8,DuLieu!$T$3:$T$101921,">=1", DuLieu!$T$3:$T$101921,"<=7",DuLieu!$U$3:$U$101921,$R8) | E8: =IF(C8>=D8,C8-D8,0) | F8: 6 | G8: =SUMIFS(DuLieu!$I$3:$I$11921,DuLieu!$B$3:$B$101921,$A8,DuLieu!$T$3:$T$101921,">=8", DuLieu!$T$3:$T$101921,"<=14",DuLieu!$U$3:$U$101921,$R8) | H8: =IF(F8>=G8,F8-G8,0) | I8: 6 | J8: =SUMIFS(DuLieu!$I$3:$I$11921,DuLieu!$B$3:$B$101921,$A8,DuLieu!$T$3:$T$101921,">=15", DuLieu!$T$3:$T$101921,"<=21",DuLieu!$U$3:$U$101921,$R8) | K8: =IF(I8>=J8,I8-J8,0) | L8: 5 | M8: =SUMIFS(DuLieu!$D$3:$D$101921,DuLieu!$B$3:$B$101921,$A8,DuLieu!$T$3:$T$101921,">=1", DuLieu!$T$3:$T$101921,"<=7",DuLieu!$U$3:$U$101921,$R8) | N8: =IF(L8>=M8,L8-M8,0) | O8: 40 | P8: =$D8+$G8+$J8+$M8 | Q8: =IF(O8>=P8,O8-P8,0) | R8: 11
A9: Trần Trung Giang | B9: CSKH HVC chuyển XGSPON | C9: 0 | D9: =SUMIFS(DuLieu!$J$3:$J$11921,DuLieu!$B$3:$B$101921,$A9,DuLieu!$T$3:$T$101921,">=1", DuLieu!$T$3:$T$101921,"<=7",DuLieu!$U$3:$U$101921,$R9) | E9: =IF(C9>=D9,C9-D9,0) | F9: 0 | G9: =SUMIFS(DuLieu!$J$3:$J$11921,DuLieu!$B$3:$B$101921,$A9,DuLieu!$T$3:$T$101921,">=8", DuLieu!$T$3:$T$101921,"<=14",DuLieu!$U$3:$U$101921,$R9) | H9: =IF(F9>=G9,F9-G9,0) | J9: =SUMIFS(DuLieu!$J$3:$J$11921,DuLieu!$B$3:$B$101921,$A9,DuLieu!$T$3:$T$101921,">=15", DuLieu!$T$3:$T$101921,"<=21",DuLieu!$U$3:$U$101921,$R9) | K9: =IF(I9>=J9,I9-J9,0) | M9: =SUMIFS(DuLieu!$D$3:$D$101921,DuLieu!$B$3:$B$101921,$A9,DuLieu!$T$3:$T$101921,">=1", DuLieu!$T$3:$T$101921,"<=7",DuLieu!$U$3:$U$101921,$R9) | N9: =IF(L9>=M9,L9-M9,0) | O9: 20 | P9: =$D9+$G9+$J9+$M9 | Q9: =IF(O9>=P9,O9-P9,0) | R9: 11
